Workbook

Sheet START HERE
A1: PCI AI — PROJECT CONTROLS INSTITUTE | EMPLOYEE EXECUTION TRACKER
A2: Read this page first. It takes 5 minutes and explains exactly how to use every tab.
A4: 1. HOW THIS WORKS — employees fill in ONE sheet
A5: EVERY DAY -> DAILY ENTRY tab | B5: This is the only sheet you must fill in. One row for each thing you did: the date, your name, which platform, what kind of work, how many, how long it took and a link that proves it. Six of the ten columns are dropdowns, so most of a row is clicking, not typing.
A6: Log as you go, not at 5pm | B6: Add the row when you finish the task. Ten rows a day is normal. If you did nothing on a platform, there is simply no row for it.
A7: ALSO, if you do LinkedIn outreach | B7: The LinkedIn Outreach tab holds one row per PERSON you contact - name, company, the message you sent, and what they replied. This cannot be collapsed into daily totals, because acceptance and reply rates need to be tracked per person.
A8: Everything else fills itself in | B8: Platform Progress, Who Did What, Team Scorecard, Weekly Review, Dashboard and Summary all calculate from what you enter. You never type a number twice. The Daily Summary tab is optional.
A9: BEFORE YOU START -> Platform Setup tab | B9: Work through the account list and follow the setup steps written in each row. Mark Status = Complete only when the profile is fully filled in with logo, bio, link and 2FA.
A10: BEFORE YOU WRITE -> Publishing Plan tab | B10: The ten publishing platforms, ranked, with the rule for each one. Read the rule before you publish anywhere.
A11: BEFORE YOU MESSAGE -> Message Bank tab | B11: Never write outreach from scratch. Copy the approved message and replace every [bracket] with real details from the person's profile.
A12: EVERY FRIDAY -> Weekly Review tab | B12: Write your wins, misses and next week's focus. The numbers are already there. Use the dropdown in cell B2 to see just your own week.
A13: REFERENCE -> How-To Guides, LinkedIn Playbook, Benchmarks | B13: Read these when you start a platform for the first time or when you want to know what good looks like.
A14: FOR THE MANAGER -> Dashboard, Team Scorecard, Platform Progress, Who Did What | B14: Four read-only pages. Nobody types in them.
A15: Master Tasks tab | B15: The full workstream list with an Owner column. Update Status and Progress when a task moves.
A17: 2. YOUR SETTINGS — fill in the yellow cells once
A18: Employee name
A19: Manager / reviewer
A20: Programme start date (a Monday) | B20: 2026-08-17
A21: Working days per week | B21: 5
A23: 3. DAILY TARGETS — agreed with your manager (blue = you may change with approval)
A24: Activity | B24: Target per day | C24: Target per week (auto)
A25: Sales Navigator leads researched | B25: 30 | C25: =B25*'START HERE'!$B$21 -> 150
A26: Connection requests sent | B26: 20 | C26: =B26*'START HERE'!$B$21 -> 100
A27: First messages sent (accepted connections) | B27: 15 | C27: =B27*'START HERE'!$B$21 -> 75
A28: Follow-up messages sent | B28: 10 | C28: =B28*'START HERE'!$B$21 -> 50
A29: Posts published (all platforms) | B29: 2 | C29: =B29*'START HERE'!$B$21 -> 10
A30: Community answers / comments (Quora, Reddit, Groups) | B30: 3 | C30: =B30*'START HERE'!$B$21 -> 15
A31: Partnership / PR contacts approached | B31: 5 | C31: =B31*'START HERE'!$B$21 -> 25
A32: Meaningful engagements (likes + comments on others) | B32: 15 | C32: =B32*'START HERE'!$B$21 -> 75
A34: 4. GOLDEN RULES — these protect PCI's reputation. Breaking them is a serious issue.
A35: 1. Be honest. Never tell anyone they have been awarded, approved or guaranteed an honorary certification. You are inviting them to be considered and sharing the criteria — nothing more.
A36: 2. Never invent facts about PCI — numbers of members, accreditations, recognition or partnerships. If you are unsure, ask your manager before you send.
A37: 3. Personalise every message. Read the profile first and reference something real (their role, employer, project type or years of experience).
A38: 4. Keep outreach messages under 300 characters and connection notes under 200 characters.
A39: 5. No bulk sending, no automation tools, no bots, no scraping. LinkedIn restricts accounts for this and it destroys reply rates.
A40: 6. Respect limits: stop at the daily target. If LinkedIn shows a warning, stop for the day and tell your manager.
A41: 7. If someone says no or asks you to stop, thank them politely and never contact them again. Mark Outcome = Declined.
A42: 8. Answer the question first, promote PCI second. On Quora, Reddit and groups a useful answer with no link beats a link with no value.
A43: 9. Never post PCI passwords in this file — only the reference name from the password manager. Turn on 2FA everywhere.
A44: 10. Log everything the same day. Evidence (a URL or screenshot link) is what makes the work count.
...

Sheet DAILY ENTRY
A1: DAILY ENTRY — this is the only sheet you need to fill in
A2: One row for each thing you did, on each platform, each day. Six of the ten columns are dropdowns. Everything else in this workbook fills itself in from here.
A3: Date | B3: Your name | C3: Platform | D3: What kind of work | E3: What exactly did you do? | F3: How many | G3: Minutes spent | H3: Link / proof | I3: Result | J3: Notes or blocker
A4: 46251 | B4: Employee 1 | C4: LinkedIn Sales Navigator | D4: Lead researched (Sales Navigator) | E4: Built a list of project controls managers in the UK rail sector | F4: 30 | G4: 60 | H4: [Sales Nav list link] | I4: Done | J4: EXAMPLE ROW - delete these three before you start
A5: 46251 | B5: Employee 1 | C5: LinkedIn | D5: Connection request sent | E5: Sent connection requests with a personal line from each profile | F5: 20 | G5: 45 | H5: logged in LinkedIn Outreach tab | I5: Done | J5: EXAMPLE ROW
A6: 46251 | B6: Employee 1 | C6: Medium | D6: Post / content published | E6: Published the article on cost control mistakes, canonical set to our site | F6: 1 | G6: 90 | H6: [article URL] | I6: Done | J6: EXAMPLE ROW

Sheet LinkedIn Outreach
A1: LINKEDIN + SALES NAVIGATOR OUTREACH LOG — one row per person
A2: Log every lead the same day. Row 4 is a worked example - your data starts on row 5. Column Q counts your message characters and turns red above 300.
A3: Date | B3: Employee | C3: Lead name | D3: LinkedIn / Sales Nav URL | E3: Company | F3: Job title | G3: Country | H3: Lead segment | I3: Sales Nav list | J3: Years exp. | K3: Qualified? | L3: Personal line used (from their profile) | M3: Connection sent? | N3: Accepted? | O3: Template used | P3: Message sent (paste the final text) | Q3: Chars | R3: Message sent? | S3: Outcome | T3: Reply summary | U3: Follow-up due | V3: Follow-ups sent | W3: Next action | X3: Notes | Y3: ICP fit (1-5) | Z3: Intent signals (1-5) | AA3: Lead score (auto) | AB3: Priority band | AC3: Funnel stage (auto)
A4: 46251 | B4: [Your name] | C4: A. Sample (example row - delete) | D4: https://www.linkedin.com/in/example | E4: Example Engineering Ltd | F4: Project Controls Manager | G4: United Kingdom | H4: Project Controls Lead | I4: PC Managers - UK | J4: 14 | K4: =IF(J4="","",IF(J4>=8,"Yes","Check")) -> Yes | L4: Led cost control on the [X] rail upgrade - mentioned it in her post last week | M4: Yes | N4: Yes | O4: M2 First Message | P4: Thanks for connecting, Anna. PCI recognises senior project controls practitioners through an honorary certification, assessed on experience and contribution rather than an exam. With 14 years at Example Engineering you may qualify. May I send you the criteria? No cost to review. - Sam | Q4: =IF(P4="","",LEN(P4)) -> 285 | R4: Yes | S4: Info Requested | T4: Asked for the criteria document and fee position | U4: =IF(OR(R4<>"Yes",A4=""),"",A4+4) -> 46255 | V4: 0 | W4: Send criteria pack, then diarise day 4 follow-up | X4: EXAMPLE ROW - shows the level of detail expected. Delete before use. | AA4: =IF(AND($Y4="",$Z4=""),"",ROUND(IFERROR(VALUE(LEFT($Y4,1)),0)*12+IFERROR(VALUE(LEFT($Z4,1)),0)*8,0)) | AB4: =IF($AA4="","",IF($AA4>=80,"A - call first",IF($AA4>=60,"B - worth pursuing",IF($AA4>=40,"C - nurture","D - do not spend time here")))) | AC4: =IF($C4="","",IF($S4="Converted","7 Certification / Enterprise opportunity",IF($S4="Application Started","7 Certification / Enterprise opportunity",IF($S4="Meeting Booked","6 Meeting / Application",IF(OR($S4="Interested",$S4="Info Requested"),"5 Interested",IF(OR($S4="Declined",$S4="Not Relevant"),"0 Closed - no",IF($R4="Yes","4 Contacted",IF($N4="Yes","2 Engaged",IF($M4="Yes","1 Awareness",IF($AA4>=60,"3 Qualified","1 Awareness")))))))))) -> 5 Interested
K5: =IF(J5="","",IF(J5>=8,"Yes","Check")) | Q5: =IF(P5="","",LEN(P5)) | U5: =IF(OR(R5<>"Yes",A5=""),"",A5+4) | AA5: =IF(AND($Y5="",$Z5=""),"",ROUND(IFERROR(VALUE(LEFT($Y5,1)),0)*12+IFERROR(VALUE(LEFT($Z5,1)),0)*8,0)) | AB5: =IF($AA5="","",IF($AA5>=80,"A - call first",IF($AA5>=60,"B - worth pursuing",IF($AA5>=40,"C - nurture","D - do not spend time here")))) | AC5: =IF($C5="","",IF($S5="Converted","7 Certification / Enterprise opportunity",IF($S5="Application Started","7 Certification / Enterprise opportunity",IF($S5="Meeting Booked","6 Meeting / Application",IF(OR($S5="Interested",$S5="Info Requested"),"5 Interested",IF(OR($S5="Declined",$S5="Not Relevant"),"0 Closed - no",IF($R5="Yes","4 Contacted",IF($N5="Yes","2 Engaged",IF($M5="Yes","1 Awareness",IF($AA5>=60,"3 Qualified","1 Awareness"))))))))))
K6: =IF(J6="","",IF(J6>=8,"Yes","Check")) | Q6: =IF(P6="","",LEN(P6)) | U6: =IF(OR(R6<>"Yes",A6=""),"",A6+4) | AA6: =IF(AND($Y6="",$Z6=""),"",ROUND(IFERROR(VALUE(LEFT($Y6,1)),0)*12+IFERROR(VALUE(LEFT($Z6,1)),0)*8,0)) | AB6: =IF($AA6="","",IF($AA6>=80,"A - call first",IF($AA6>=60,"B - worth pursuing",IF($AA6>=40,"C - nurture","D - do not spend time here")))) | AC6: =IF($C6="","",IF($S6="Converted","7 Certification / Enterprise opportunity",IF($S6="Application Started","7 Certification / Enterprise opportunity",IF($S6="Meeting Booked","6 Meeting / Application",IF(OR($S6="Interested",$S6="Info Requested"),"5 Interested",IF(OR($S6="Declined",$S6="Not Relevant"),"0 Closed - no",IF($R6="Yes","4 Contacted",IF($N6="Yes","2 Engaged",IF($M6="Yes","1 Awareness",IF($AA6>=60,"3 Qualified","1 Awareness"))))))))))
K7: =IF(J7="","",IF(J7>=8,"Yes","Check")) | Q7: =IF(P7="","",LEN(P7)) | U7: =IF(OR(R7<>"Yes",A7=""),"",A7+4) | AA7: =IF(AND($Y7="",$Z7=""),"",ROUND(IFERROR(VALUE(LEFT($Y7,1)),0)*12+IFERROR(VALUE(LEFT($Z7,1)),0)*8,0)) | AB7: =IF($AA7="","",IF($AA7>=80,"A - call first",IF($AA7>=60,"B - worth pursuing",IF($AA7>=40,"C - nurture","D - do not spend time here")))) | AC7: =IF($C7="","",IF($S7="Converted","7 Certification / Enterprise opportunity",IF($S7="Application Started","7 Certification / Enterprise opportunity",IF($S7="Meeting Booked","6 Meeting / Application",IF(OR($S7="Interested",$S7="Info Requested"),"5 Interested",IF(OR($S7="Declined",$S7="Not Relevant"),"0 Closed - no",IF($R7="Yes","4 Contacted",IF($N7="Yes","2 Engaged",IF($M7="Yes","1 Awareness",IF($AA7>=60,"3 Qualified","1 Awareness"))))))))))
K8: =IF(J8="","",IF(J8>=8,"Yes","Check")) | Q8: =IF(P8="","",LEN(P8)) | U8: =IF(OR(R8<>"Yes",A8=""),"",A8+4) | AA8: =IF(AND($Y8="",$Z8=""),"",ROUND(IFERROR(VALUE(LEFT($Y8,1)),0)*12+IFERROR(VALUE(LEFT($Z8,1)),0)*8,0)) | AB8: =IF($AA8="","",IF($AA8>=80,"A - call first",IF($AA8>=60,"B - worth pursuing",IF($AA8>=40,"C - nurture","D - do not spend time here")))) | AC8: =IF($C8="","",IF($S8="Converted","7 Certification / Enterprise opportunity",IF($S8="Application Started","7 Certification / Enterprise opportunity",IF($S8="Meeting Booked","6 Meeting / Application",IF(OR($S8="Interested",$S8="Info Requested"),"5 Interested",IF(OR($S8="Declined",$S8="Not Relevant"),"0 Closed - no",IF($R8="Yes","4 Contacted",IF($N8="Yes","2 Engaged",IF($M8="Yes","1 Awareness",IF($AA8>=60,"3 Qualified","1 Awareness"))))))))))
K9: =IF(J9="","",IF(J9>=8,"Yes","Check")) | Q9: =IF(P9="","",LEN(P9)) | U9: =IF(OR(R9<>"Yes",A9=""),"",A9+4) | AA9: =IF(AND($Y9="",$Z9=""),"",ROUND(IFERROR(VALUE(LEFT($Y9,1)),0)*12+IFERROR(VALUE(LEFT($Z9,1)),0)*8,0)) | AB9: =IF($AA9="","",IF($AA9>=80,"A - call first",IF($AA9>=60,"B - worth pursuing",IF($AA9>=40,"C - nurture","D - do not spend time here")))) | AC9: =IF($C9="","",IF($S9="Converted","7 Certification / Enterprise opportunity",IF($S9="Application Started","7 Certification / Enterprise opportunity",IF($S9="Meeting Booked","6 Meeting / Application",IF(OR($S9="Interested",$S9="Info Requested"),"5 Interested",IF(OR($S9="Declined",$S9="Not Relevant"),"0 Closed - no",IF($R9="Yes","4 Contacted",IF($N9="Yes","2 Engaged",IF($M9="Yes","1 Awareness",IF($AA9>=60,"3 Qualified","1 Awareness"))))))))))
K10: =IF(J10="","",IF(J10>=8,"Yes","Check")) | Q10: =IF(P10="","",LEN(P10)) | U10: =IF(OR(R10<>"Yes",A10=""),"",A10+4) | AA10: =IF(AND($Y10="",$Z10=""),"",ROUND(IFERROR(VALUE(LEFT($Y10,1)),0)*12+IFERROR(VALUE(LEFT($Z10,1)),0)*8,0)) | AB10: =IF($AA10="","",IF($AA10>=80,"A - call first",IF($AA10>=60,"B - worth pursuing",IF($AA10>=40,"C - nurture","D - do not spend time here")))) | AC10: =IF($C10="","",IF($S10="Converted","7 Certification / Enterprise opportunity",IF($S10="Application Started","7 Certification / Enterprise opportunity",IF($S10="Meeting Booked","6 Meeting / Application",IF(OR($S10="Interested",$S10="Info Requested"),"5 Interested",IF(OR($S10="Declined",$S10="Not Relevant"),"0 Closed - no",IF($R10="Yes","4 Contacted",IF($N10="Yes","2 Engaged",IF($M10="Yes","1 Awareness",IF($AA10>=60,"3 Qualified","1 Awareness"))))))))))
K11: =IF(J11="","",IF(J11>=8,"Yes","Check")) | Q11: =IF(P11="","",LEN(P11)) | U11: =IF(OR(R11<>"Yes",A11=""),"",A11+4) | AA11: =IF(AND($Y11="",$Z11=""),"",ROUND(IFERROR(VALUE(LEFT($Y11,1)),0)*12+IFERROR(VALUE(LEFT($Z11,1)),0)*8,0)) | AB11: =IF($AA11="","",IF($AA11>=80,"A - call first",IF($AA11>=60,"B - worth pursuing",IF($AA11>=40,"C - nurture","D - do not spend time here")))) | AC11: =IF($C11="","",IF($S11="Converted","7 Certification / Enterprise opportunity",IF($S11="Application Started","7 Certification / Enterprise opportunity",IF($S11="Meeting Booked","6 Meeting / Application",IF(OR($S11="Interested",$S11="Info Requested"),"5 Interested",IF(OR($S11="Declined",$S11="Not Relevant"),"0 Closed - no",IF($R11="Yes","4 Contacted",IF($N11="Yes","2 Engaged",IF($M11="Yes","1 Awareness",IF($AA11>=60,"3 Qualified","1 Awareness"))))))))))
K12: =IF(J12="","",IF(J12>=8,"Yes","Check")) | Q12: =IF(P12="","",LEN(P12)) | U12: =IF(OR(R12<>"Yes",A12=""),"",A12+4) | AA12: =IF(AND($Y12="",$Z12=""),"",ROUND(IFERROR(VALUE(LEFT($Y12,1)),0)*12+IFERROR(VALUE(LEFT($Z12,1)),0)*8,0)) | AB12: =IF($AA12="","",IF($AA12>=80,"A - call first",IF($AA12>=60,"B - worth pursuing",IF($AA12>=40,"C - nurture","D - do not spend time here")))) | AC12: =IF($C12="","",IF($S12="Converted","7 Certification / Enterprise opportunity",IF($S12="Application Started","7 Certification / Enterprise opportunity",IF($S12="Meeting Booked","6 Meeting / Application",IF(OR($S12="Interested",$S12="Info Requested"),"5 Interested",IF(OR($S12="Declined",$S12="Not Relevant"),"0 Closed - no",IF($R12="Yes","4 Contacted",IF($N12="Yes","2 Engaged",IF($M12="Yes","1 Awareness",IF($AA12>=60,"3 Qualified","1 Awareness"))))))))))
K13: =IF(J13="","",IF(J13>=8,"Yes","Check")) | Q13: =IF(P13="","",LEN(P13)) | U13: =IF(OR(R13<>"Yes",A13=""),"",A13+4) | AA13: =IF(AND($Y13="",$Z13=""),"",ROUND(IFERROR(VALUE(LEFT($Y13,1)),0)*12+IFERROR(VALUE(LEFT($Z13,1)),0)*8,0)) | AB13: =IF($AA13="","",IF($AA13>=80,"A - call first",IF($AA13>=60,"B - worth pursuing",IF($AA13>=40,"C - nurture","D - do not spend time here")))) | AC13: =IF($C13="","",IF($S13="Converted","7 Certification / Enterprise opportunity",IF($S13="Application Started","7 Certification / Enterprise opportunity",IF($S13="Meeting Booked","6 Meeting / Application",IF(OR($S13="Interested",$S13="Info Requested"),"5 Interested",IF(OR($S13="Declined",$S13="Not Relevant"),"0 Closed - no",IF($R13="Yes","4 Contacted",IF($N13="Yes","2 Engaged",IF($M13="Yes","1 Awareness",IF($AA13>=60,"3 Qualified","1 Awareness"))))))))))
K14: =IF(J14="","",IF(J14>=8,"Yes","Check")) | Q14: =IF(P14="","",LEN(P14)) | U14: =IF(OR(R14<>"Yes",A14=""),"",A14+4) | AA14: =IF(AND($Y14="",$Z14=""),"",ROUND(IFERROR(VALUE(LEFT($Y14,1)),0)*12+IFERROR(VALUE(LEFT($Z14,1)),0)*8,0)) | AB14: =IF($AA14="","",IF($AA14>=80,"A - call first",IF($AA14>=60,"B - worth pursuing",IF($AA14>=40,"C - nurture","D - do not spend time here")))) | AC14: =IF($C14="","",IF($S14="Converted","7 Certification / Enterprise opportunity",IF($S14="Application Started","7 Certification / Enterprise opportunity",IF($S14="Meeting Booked","6 Meeting / Application",IF(OR($S14="Interested",$S14="Info Requested"),"5 Interested",IF(OR($S14="Declined",$S14="Not Relevant"),"0 Closed - no",IF($R14="Yes","4 Contacted",IF($N14="Yes","2 Engaged",IF($M14="Yes","1 Awareness",IF($AA14>=60,"3 Qualified","1 Awareness"))))))))))
K15: =IF(J15="","",IF(J15>=8,"Yes","Check")) | Q15: =IF(P15="","",LEN(P15)) | U15: =IF(OR(R15<>"Yes",A15=""),"",A15+4) | AA15: =IF(AND($Y15="",$Z15=""),"",ROUND(IFERROR(VALUE(LEFT($Y15,1)),0)*12+IFERROR(VALUE(LEFT($Z15,1)),0)*8,0)) | AB15: =IF($AA15="","",IF($AA15>=80,"A - call first",IF($AA15>=60,"B - worth pursuing",IF($AA15>=40,"C - nurture","D - do not spend time here")))) | AC15: =IF($C15="","",IF($S15="Converted","7 Certification / Enterprise opportunity",IF($S15="Application Started","7 Certification / Enterprise opportunity",IF($S15="Meeting Booked","6 Meeting / Application",IF(OR($S15="Interested",$S15="Info Requested"),"5 Interested",IF(OR($S15="Declined",$S15="Not Relevant"),"0 Closed - no",IF($R15="Yes","4 Contacted",IF($N15="Yes","2 Engaged",IF($M15="Yes","1 Awareness",IF($AA15>=60,"3 Qualified","1 Awareness"))))))))))
K16: =IF(J16="","",IF(J16>=8,"Yes","Check")) | Q16: =IF(P16="","",LEN(P16)) | U16: =IF(OR(R16<>"Yes",A16=""),"",A16+4) | AA16: =IF(AND($Y16="",$Z16=""),"",ROUND(IFERROR(VALUE(LEFT($Y16,1)),0)*12+IFERROR(VALUE(LEFT($Z16,1)),0)*8,0)) | AB16: =IF($AA16="","",IF($AA16>=80,"A - call first",IF($AA16>=60,"B - worth pursuing",IF($AA16>=40,"C - nurture","D - do not spend time here")))) | AC16: =IF($C16="","",IF($S16="Converted","7 Certification / Enterprise opportunity",IF($S16="Application Started","7 Certification / Enterprise opportunity",IF($S16="Meeting Booked","6 Meeting / Application",IF(OR($S16="Interested",$S16="Info Requested"),"5 Interested",IF(OR($S16="Declined",$S16="Not Relevant"),"0 Closed - no",IF($R16="Yes","4 Contacted",IF($N16="Yes","2 Engaged",IF($M16="Yes","1 Awareness",IF($AA16>=60,"3 Qualified","1 Awareness"))))))))))
... K1203: =IF(J1203="","",IF(J1203>=8,"Yes","Check")) | Q1203: =IF(P1203="","",LEN(P1203)) | U1203: =IF(OR(R1203<>"Yes",A1203=""),"",A1203+4) | AA1203: =IF(AND($Y1203="",$Z1203=""),"",ROUND(IFERROR(VALUE(LEFT($Y1203,1)),0)*12+IFERROR(VALUE(LEFT($Z1203,1)),0)*8,0)) | AB1203: =IF($AA1203="","",IF($AA1203>=80,"A - call first",IF($AA1203>=60,"B - worth pursuing",IF($AA1203>=40,"C - nurture","D - do not spend time here")))) | AC1203: =IF($C1203="","",IF($S1203="Converted","7 Certification / Enterprise opportunity",IF($S1203="Application Started","7 Certification / Enterprise opportunity",IF($S1203="Meeting Booked","6 Meeting / Application",IF(OR($S1203="Interested",$S1203="Info Requested"),"5 Interested",IF(OR($S1203="Declined",$S1203="Not Relevant"),"0 Closed - no",IF($R1203="Yes","4 Contacted",IF($N1203="Yes","2 Engaged",IF($M1203="Yes","1 Awareness",IF($AA1203>=60,"3 Qualified","1 Awareness"))))))))))

Sheet Partnership Pipeline
A1: PARTNERSHIP PIPELINE — employers, universities, associations, influencers, media
A2: One row per organisation. A single association or employer partnership is worth hundreds of individual messages, so these get scored and staged like deals.
A3: Date opened | B3: Owner | C3: Organisation | D3: Type | E3: Country | F3: Contact name | G3: Contact role | H3: LinkedIn / URL | I3: Why them (the fit) | J3: ICP fit (1-5) | K3: Intent signals (1-5) | L3: Score (auto) | M3: Band (auto) | N3: Stage | O3: Potential value | P3: What they get | Q3: Last contact | R3: Next step | S3: Next step due | T3: Status | U3: Notes
A4: 46251 | B4: Employee 1 | C4: Example Rail Group | D4: Enterprise / Employer | E4: United Kingdom | F4: A. Sample | G4: Head of PMO | H4: [LinkedIn URL] | I4: 300+ project controls staff, no internal credentialing route, actively hiring planners | J4: 5 - excellent | K4: 3 - average | L4: =IF(AND($J4="",$K4=""),"",ROUND(IFERROR(VALUE(LEFT($J4,1)),0)*12+IFERROR(VALUE(LEFT($K4,1)),0)*8,0)) -> 84 | M4: =IF($L4="","",IF($L4>=80,"A - pursue now",IF($L4>=60,"B - worth pursuing",IF($L4>=40,"C - nurture","D - park it")))) -> A - pursue now | N4: 4 Contacted | O4: High | P4: A benchmarked capability picture of their project controls team | Q4: 46251 | R4: Send the one-page overview and propose a 20-minute call | S4: 46255 | T4: In Progress | U4: EXAMPLE ROW - delete before use
L5: =IF(AND($J5="",$K5=""),"",ROUND(IFERROR(VALUE(LEFT($J5,1)),0)*12+IFERROR(VALUE(LEFT($K5,1)),0)*8,0)) | M5: =IF($L5="","",IF($L5>=80,"A - pursue now",IF($L5>=60,"B - worth pursuing",IF($L5>=40,"C - nurture","D - park it"))))
L6: =IF(AND($J6="",$K6=""),"",ROUND(IFERROR(VALUE(LEFT($J6,1)),0)*12+IFERROR(VALUE(LEFT($K6,1)),0)*8,0)) | M6: =IF($L6="","",IF($L6>=80,"A - pursue now",IF($L6>=60,"B - worth pursuing",IF($L6>=40,"C - nurture","D - park it"))))
L7: =IF(AND($J7="",$K7=""),"",ROUND(IFERROR(VALUE(LEFT($J7,1)),0)*12+IFERROR(VALUE(LEFT($K7,1)),0)*8,0)) | M7: =IF($L7="","",IF($L7>=80,"A - pursue now",IF($L7>=60,"B - worth pursuing",IF($L7>=40,"C - nurture","D - park it"))))
L8: =IF(AND($J8="",$K8=""),"",ROUND(IFERROR(VALUE(LEFT($J8,1)),0)*12+IFERROR(VALUE(LEFT($K8,1)),0)*8,0)) | M8: =IF($L8="","",IF($L8>=80,"A - pursue now",IF($L8>=60,"B - worth pursuing",IF($L8>=40,"C - nurture","D - park it"))))
L9: =IF(AND($J9="",$K9=""),"",ROUND(IFERROR(VALUE(LEFT($J9,1)),0)*12+IFERROR(VALUE(LEFT($K9,1)),0)*8,0)) | M9: =IF($L9="","",IF($L9>=80,"A - pursue now",IF($L9>=60,"B - worth pursuing",IF($L9>=40,"C - nurture","D - park it"))))
L10: =IF(AND($J10="",$K10=""),"",ROUND(IFERROR(VALUE(LEFT($J10,1)),0)*12+IFERROR(VALUE(LEFT($K10,1)),0)*8,0)) | M10: =IF($L10="","",IF($L10>=80,"A - pursue now",IF($L10>=60,"B - worth pursuing",IF($L10>=40,"C - nurture","D - park it"))))
L11: =IF(AND($J11="",$K11=""),"",ROUND(IFERROR(VALUE(LEFT($J11,1)),0)*12+IFERROR(VALUE(LEFT($K11,1)),0)*8,0)) | M11: =IF($L11="","",IF($L11>=80,"A - pursue now",IF($L11>=60,"B - worth pursuing",IF($L11>=40,"C - nurture","D - park it"))))
L12: =IF(AND($J12="",$K12=""),"",ROUND(IFERROR(VALUE(LEFT($J12,1)),0)*12+IFERROR(VALUE(LEFT($K12,1)),0)*8,0)) | M12: =IF($L12="","",IF($L12>=80,"A - pursue now",IF($L12>=60,"B - worth pursuing",IF($L12>=40,"C - nurture","D - park it"))))
L13: =IF(AND($J13="",$K13=""),"",ROUND(IFERROR(VALUE(LEFT($J13,1)),0)*12+IFERROR(VALUE(LEFT($K13,1)),0)*8,0)) | M13: =IF($L13="","",IF($L13>=80,"A - pursue now",IF($L13>=60,"B - worth pursuing",IF($L13>=40,"C - nurture","D - park it"))))
L14: =IF(AND($J14="",$K14=""),"",ROUND(IFERROR(VALUE(LEFT($J14,1)),0)*12+IFERROR(VALUE(LEFT($K14,1)),0)*8,0)) | M14: =IF($L14="","",IF($L14>=80,"A - pursue now",IF($L14>=60,"B - worth pursuing",IF($L14>=40,"C - nurture","D - park it"))))
L15: =IF(AND($J15="",$K15=""),"",ROUND(IFERROR(VALUE(LEFT($J15,1)),0)*12+IFERROR(VALUE(LEFT($K15,1)),0)*8,0)) | M15: =IF($L15="","",IF($L15>=80,"A - pursue now",IF($L15>=60,"B - worth pursuing",IF($L15>=40,"C - nurture","D - park it"))))
L16: =IF(AND($J16="",$K16=""),"",ROUND(IFERROR(VALUE(LEFT($J16,1)),0)*12+IFERROR(VALUE(LEFT($K16,1)),0)*8,0)) | M16: =IF($L16="","",IF($L16>=80,"A - pursue now",IF($L16>=60,"B - worth pursuing",IF($L16>=40,"C - nurture","D - park it"))))
... L403: =IF(AND($J403="",$K403=""),"",ROUND(IFERROR(VALUE(LEFT($J403,1)),0)*12+IFERROR(VALUE(LEFT($K403,1)),0)*8,0)) | M403: =IF($L403="","",IF($L403>=80,"A - pursue now",IF($L403>=60,"B - worth pursuing",IF($L403>=40,"C - nurture","D - park it"))))

Sheet Dashboard
A1: PCI AI — EXECUTION DASHBOARD
A2: Nothing is typed on this page. Every figure updates from the other tabs. Press Ctrl+Shift+F9 if a figure looks stale. | H2: Chart data (do not delete)
A4: 1. TASK EXECUTION (from Master Tasks) | H4: Not Started | I4: =COUNTIF('Master Tasks'!$J$4:$J$66,H4) -> 63
A5: Metric | B5: Value | C5: Target / benchmark | D5: Status | E5: What it tells management | H5: In Progress | I5: =COUNTIF('Master Tasks'!$J$4:$J$66,H5) -> 0
A6: Total tasks in the plan | B6: =COUNTA('Master Tasks'!$A$4:$A$66) -> 63 | C6: 63 | E6: Size of the agreed workload. | H6: Waiting | I6: =COUNTIF('Master Tasks'!$J$4:$J$66,H6) -> 0
A7: Complete | B7: =COUNTIF('Master Tasks'!$J$4:$J$66,"Complete") -> 0 | E7: Finished and evidenced. | H7: Blocked | I7: =COUNTIF('Master Tasks'!$J$4:$J$66,H7) -> 0
A8: In progress | B8: =COUNTIF('Master Tasks'!$J$4:$J$66,"In Progress") -> 0 | E8: Being actively worked on. | H8: Complete | I8: =COUNTIF('Master Tasks'!$J$4:$J$66,H8) -> 0
A9: Waiting / paused | B9: =COUNTIF('Master Tasks'!$J$4:$J$66,"Waiting")+COUNTIF('Master Tasks'!$J$4:$J$66,"Paused") -> 0 | E9: Held up but not blocked. | H9: Paused | I9: =COUNTIF('Master Tasks'!$J$4:$J$66,H9) -> 0
A10: Blocked - needs management help | B10: =COUNTIF('Master Tasks'!$J$4:$J$66,"Blocked") -> 0 | C10: 0 | E10: Anything above zero needs a decision from the manager this week.
A11: Not started | B11: =COUNTIF('Master Tasks'!$J$4:$J$66,"Not Started") -> 63 | E11: Not yet begun.
A12: Task completion rate | B12: =IFERROR(COUNTIF('Master Tasks'!$J$4:$J$66,"Complete")/COUNTA('Master Tasks'!$A$4:$A$66),0) -> 0 | C12: 100% | E12: Share of the plan finished. | H12: Not Started | I12: =COUNTIF('Platform Setup'!$J$4:$J$49,H12) -> 46
A13: Average progress across all tasks | B13: =IFERROR(AVERAGE('Master Tasks'!$K$4:$K$66),0) -> 0 | C13: 100% | E13: Weighted sense of momentum, including part-finished work. | H13: In Progress | I13: =COUNTIF('Platform Setup'!$J$4:$J$49,H13) -> 0
H14: Waiting | I14: =COUNTIF('Platform Setup'!$J$4:$J$49,H14) -> 0
A15: 2. PLATFORM PRESENCE (from Platform Setup) | H15: Blocked | I15: =COUNTIF('Platform Setup'!$J$4:$J$49,H15) -> 0
A16: Metric | B16: Value | C16: Target / benchmark | D16: Status | E16: What it tells management | H16: Complete | I16: =COUNTIF('Platform Setup'!$J$4:$J$49,H16) -> 0
A17: Platforms in scope | B17: =COUNTA('Platform Setup'!$B$4:$B$49) -> 46 | C17: 46 | E17: Every channel PCI should exist on. | H17: Paused | I17: =COUNTIF('Platform Setup'!$J$4:$J$49,H17) -> 0
A18: Accounts live and complete | B18: =COUNTIF('Platform Setup'!$J$4:$J$49,"Complete") -> 0 | E18: Fully branded, filled in and 2FA enabled.
A19: In progress | B19: =COUNTIF('Platform Setup'!$J$4:$J$49,"In Progress") -> 0 | E19: Created but not finished.
A20: Not started | B20: =COUNTIF('Platform Setup'!$J$4:$J$49,"Not Started") -> 46 | C20: 0 | E20: Still no PCI presence.
A21: Platform coverage | B21: =IFERROR(COUNTIF('Platform Setup'!$J$4:$J$49,"Complete")/COUNTA('Platform Setup'!$B$4:$B$49),0) -> 0 | C21: 100% | E21: The headline 'are we everywhere yet' number.
A22: Live accounts without 2FA | B22: =COUNTIFS('Platform Setup'!$I$4:$I$49,"No",'Platform Setup'!$J$4:$J$49,"<>Not Started") -> 0 | C22: 0 | E22: Security risk - every live account must have 2FA.
A24: 3. LINKEDIN OUTREACH FUNNEL (from LinkedIn Outreach)
A25: Metric | B25: Value | C25: Target / benchmark | D25: Status | E25: What it tells management
A26: Leads researched and logged | B26: =COUNTA('LinkedIn Outreach'!$C$5:$C$1203) -> 0 | E26: Top of the funnel.
A27: Connection requests sent | B27: =COUNTIF('LinkedIn Outreach'!$M$5:$M$1203,"Yes") -> 0 | E27: Invitations sent with a personalised note.
A28: Connections accepted | B28: =COUNTIF('LinkedIn Outreach'!$N$5:$N$1203,"Yes") -> 0 | E28: Accepted invitations.
A29: Acceptance rate | B29: =IFERROR(COUNTIF('LinkedIn Outreach'!$N$5:$N$1203,"Yes")/COUNTIF('LinkedIn Outreach'!$M$5:$M$1203,"Yes"),0) -> 0 | C29: 30-45% | E29: 2026 industry average is 27-30%. Below 20% means fix the targeting, profile or note before sending more.
A30: Honorary certification messages sent | B30: =COUNTIF('LinkedIn Outreach'!$R$5:$R$1203,"Yes") -> 0 | E30: The 300-character message actually delivered.
A31: Positive replies (interested / info requested) | B31: =COUNTIF('LinkedIn Outreach'!$S$5:$S$1203,"Interested")+COUNTIF('LinkedIn Outreach'!$S$5:$S$1203,"Info Requested") -> 0 | E31: Real interest created.
A32: Reply rate on messages sent | B32: =IFERROR((COUNTIF('LinkedIn Outreach'!$S$5:$S$1203,"Interested")+COUNTIF('LinkedIn Outreach'!$S$5:$S$1203,"Info Requested")+COUNTIF('LinkedIn Outreach'!$S$5:$S$1203,"Meeting Booked")+COUNTIF('LinkedIn Outreach'!$S$5:$S$1203,"Converted"))/COUNTIF('LinkedIn Outreach'!$R$5:$R$1203,"Yes"),0) -> 0 | C32: 15%+ | E32: 2026 average for post-connection messages is about 10%. 15%+ is strong.
A33: Meetings / calls booked | B33: =COUNTIF('LinkedIn Outreach'!$S$5:$S$1203,"Meeting Booked") -> 0 | E33: Conversations that management can join.
A34: Applications started / converted | B34: =COUNTIF('LinkedIn Outreach'!$S$5:$S$1203,"Application Started")+COUNTIF('LinkedIn Outreach'!$S$5:$S$1203,"Converted") -> 0 | E34: The outcome that matters commercially.
A35: Declined - do not contact again | B35: =COUNTIF('LinkedIn Outreach'!$S$5:$S$1203,"Declined") -> 0 | E35: Must never be messaged again.
A36: Messages over the 300-character limit | B36: =COUNTIF('LinkedIn Outreach'!$Q$5:$Q$1203,">300") -> 0 | C36: 0 | E36: Anything above zero means the limit was broken - check the message text.
A37: Follow-ups due today or earlier | B37: =COUNTIFS('LinkedIn Outreach'!$U$5:$U$1203,"<="&TODAY(),'LinkedIn Outreach'!$U$5:$U$1203,">0",'LinkedIn Outreach'!$S$5:$S$1203,"Awaiting Reply") -> 0 | C37: 0 | E37: Work waiting to be done today.
A39: 4. ACTIVITY VERSUS DAILY TARGET (from Daily Log)
A40: Activity | B40: Actual to date | C40: Expected to date | D40: Attainment | E40: Notes
A41: Days with activity logged | B41: =SUMPRODUCT(('DAILY ENTRY'!$A$7:$A$1203<>"")/COUNTIFS('DAILY ENTRY'!$A$7:$A$1203,'DAILY ENTRY'!$A$7:$A$1203&"")) -> 0 | E41: Counted from the DAILY ENTRY tab. The expected figures below are this number multiplied by the daily target on START HERE.
A42: Sales Navigator leads researched | B42: =SUMIFS('DAILY ENTRY'!$F$7:$F$1203,'DAILY ENTRY'!$D$7:$D$1203,"Lead researched (Sales Navigator)") -> 0 | C42: ='START HERE'!$B$25*$B$41 -> 0 | D42: =IFERROR(B42/C42,0) -> 0 | E42: =IF(C42=0,"No days logged yet",IF(D42>=1,"On target",IF(D42>=0.8,"Slightly behind - recoverable this week","Behind target - discuss in the weekly review"))) -> No days logged yet
A43: Connection requests sent | B43: =SUMIFS('DAILY ENTRY'!$F$7:$F$1203,'DAILY ENTRY'!$D$7:$D$1203,"Connection request sent") -> 0 | C43: ='START HERE'!$B$26*$B$41 -> 0 | D43: =IFERROR(B43/C43,0) -> 0 | E43: =IF(C43=0,"No days logged yet",IF(D43>=1,"On target",IF(D43>=0.8,"Slightly behind - recoverable this week","Behind target - discuss in the weekly review"))) -> No days logged yet
...

Sheet Employee Score
A1: EMPLOYEE SCORE — scored on outcomes, not on how many messages were sent
A2: Every component rewards qualified prospects, acceptance, replies, meetings and conversions. Volume is only a gate: it can cap the score, it can never raise it.
A3: Employee | B3: Lead quality (15) | C3: Acceptance rate (20) | D3: Reply rate (20) | E3: Positive replies (10) | F3: Meetings & applications (20) | G3: Downstream results (10) | H3: Compliance (5) | I3: TOTAL / 100 | J3: Grade | K3: Activity gate | L3: What to fix first
A4: =IF('START HERE'!$B$55="","",'START HERE'!$B$55) -> Employee 1 | B4: =IF($A4="","",ROUND(IFERROR(AVERAGEIFS('LinkedIn Outreach'!$AA$5:$AA$1203,'LinkedIn Outreach'!$B$5:$B$1203,$A4,'LinkedIn Outreach'!$AA$5:$AA$1203,">0"),0)/100*15,1)) -> 0 | C4: =IF($A4="","",ROUND(MIN(1,IFERROR('Team Scorecard'!F4/0.3,0))*20,1)) -> 0 | D4: =IF($A4="","",ROUND(MIN(1,IFERROR('Team Scorecard'!I4/0.15,0))*20,1)) -> 0 | E4: =IF($A4="","",ROUND(MIN(1,IFERROR('Team Scorecard'!H4/MAX(1,'Team Scorecard'!G4)/0.2,0))*10,1)) -> 0 | F4: =IF($A4="","",ROUND(MIN(1,(COUNTIFS('LinkedIn Outreach'!$B$5:$B$1203,$A4,'LinkedIn Outreach'!$AC$5:$AC$1203,"6 Meeting / Application")+COUNTIFS('LinkedIn Outreach'!$B$5:$B$1203,$A4,'LinkedIn Outreach'!$AC$5:$AC$1203,"7 Certification / Enterprise opportunity"))/5)*20,1)) -> 0 | G4: =IF($A4="","",ROUND(MIN(1,COUNTIFS('LinkedIn Outreach'!$B$5:$B$1203,$A4,'LinkedIn Outreach'!$AC$5:$AC$1203,"7 Certification / Enterprise opportunity")/3)*10,1)) -> 0 | H4: =IF($A4="","",MAX(0,5-'Team Scorecard'!O4*2.5)) -> 5 | I4: =IF($A4="","",ROUND(SUM(B4:H4),1)) -> 5 | J4: =IF($A4="","",IF(I4>=80,"A - excellent",IF(I4>=65,"B - solid",IF(I4>=50,"C - needs coaching",IF(I4>=30,"D - at risk","E - not working"))))) -> E - not working | K4: =IF($A4="","",IF('Team Scorecard'!B4=0,"No activity logged",IF('Team Scorecard'!D4<20,"Too little data to score fairly yet","Enough data"))) -> No activity logged | L4: =IF($A4="","",IF(H4<5,"Compliance first: messages were sent over the 300-character limit.",IF(C4<10,"Targeting: acceptance is well below benchmark. Fix who is being approached and the personal line.",IF(D4<10,"Message quality: people accept but do not reply. Rewrite the opening message.",IF(F4<10,"Conversion: replies are not turning into meetings. Work on the ask and the follow-through.",IF(B4<8,"Lead quality: the prospects being researched score low on fit. Tighten the Sales Navigator filters.","Nothing structural - keep going and raise the volume gradually.")))))) -> Targeting: acceptance is well below benchmark. Fix who is being approached and the personal line.
A5: =IF('START HERE'!$B$56="","",'START HERE'!$B$56) | B5: =IF($A5="","",ROUND(IFERROR(AVERAGEIFS('LinkedIn Outreach'!$AA$5:$AA$1203,'LinkedIn Outreach'!$B$5:$B$1203,$A5,'LinkedIn Outreach'!$AA$5:$AA$1203,">0"),0)/100*15,1)) | C5: =IF($A5="","",ROUND(MIN(1,IFERROR('Team Scorecard'!F5/0.3,0))*20,1)) | D5: =IF($A5="","",ROUND(MIN(1,IFERROR('Team Scorecard'!I5/0.15,0))*20,1)) | E5: =IF($A5="","",ROUND(MIN(1,IFERROR('Team Scorecard'!H5/MAX(1,'Team Scorecard'!G5)/0.2,0))*10,1)) | F5: =IF($A5="","",ROUND(MIN(1,(COUNTIFS('LinkedIn Outreach'!$B$5:$B$1203,$A5,'LinkedIn Outreach'!$AC$5:$AC$1203,"6 Meeting / Application")+COUNTIFS('LinkedIn Outreach'!$B$5:$B$1203,$A5,'LinkedIn Outreach'!$AC$5:$AC$1203,"7 Certification / Enterprise opportunity"))/5)*20,1)) | G5: =IF($A5="","",ROUND(MIN(1,COUNTIFS('LinkedIn Outreach'!$B$5:$B$1203,$A5,'LinkedIn Outreach'!$AC$5:$AC$1203,"7 Certification / Enterprise opportunity")/3)*10,1)) | H5: =IF($A5="","",MAX(0,5-'Team Scorecard'!O5*2.5)) | I5: =IF($A5="","",ROUND(SUM(B5:H5),1)) | J5: =IF($A5="","",IF(I5>=80,"A - excellent",IF(I5>=65,"B - solid",IF(I5>=50,"C - needs coaching",IF(I5>=30,"D - at risk","E - not working"))))) | K5: =IF($A5="","",IF('Team Scorecard'!B5=0,"No activity logged",IF('Team Scorecard'!D5<20,"Too little data to score fairly yet","Enough data"))) | L5: =IF($A5="","",IF(H5<5,"Compliance first: messages were sent over the 300-character limit.",IF(C5<10,"Targeting: acceptance is well below benchmark. Fix who is being approached and the personal line.",IF(D5<10,"Message quality: people accept but do not reply. Rewrite the opening message.",IF(F5<10,"Conversion: replies are not turning into meetings. Work on the ask and the follow-through.",IF(B5<8,"Lead quality: the prospects being researched score low on fit. Tighten the Sales Navigator filters.","Nothing structural - keep going and raise the volume gradually."))))))
A6: =IF('START HERE'!$B$57="","",'START HERE'!$B$57) | B6: =IF($A6="","",ROUND(IFERROR(AVERAGEIFS('LinkedIn Outreach'!$AA$5:$AA$1203,'LinkedIn Outreach'!$B$5:$B$1203,$A6,'LinkedIn Outreach'!$AA$5:$AA$1203,">0"),0)/100*15,1)) | C6: =IF($A6="","",ROUND(MIN(1,IFERROR('Team Scorecard'!F6/0.3,0))*20,1)) | D6: =IF($A6="","",ROUND(MIN(1,IFERROR('Team Scorecard'!I6/0.15,0))*20,1)) | E6: =IF($A6="","",ROUND(MIN(1,IFERROR('Team Scorecard'!H6/MAX(1,'Team Scorecard'!G6)/0.2,0))*10,1)) | F6: =IF($A6="","",ROUND(MIN(1,(COUNTIFS('LinkedIn Outreach'!$B$5:$B$1203,$A6,'LinkedIn Outreach'!$AC$5:$AC$1203,"6 Meeting / Application")+COUNTIFS('LinkedIn Outreach'!$B$5:$B$1203,$A6,'LinkedIn Outreach'!$AC$5:$AC$1203,"7 Certification / Enterprise opportunity"))/5)*20,1)) | G6: =IF($A6="","",ROUND(MIN(1,COUNTIFS('LinkedIn Outreach'!$B$5:$B$1203,$A6,'LinkedIn Outreach'!$AC$5:$AC$1203,"7 Certification / Enterprise opportunity")/3)*10,1)) | H6: =IF($A6="","",MAX(0,5-'Team Scorecard'!O6*2.5)) | I6: =IF($A6="","",ROUND(SUM(B6:H6),1)) | J6: =IF($A6="","",IF(I6>=80,"A - excellent",IF(I6>=65,"B - solid",IF(I6>=50,"C - needs coaching",IF(I6>=30,"D - at risk","E - not working"))))) | K6: =IF($A6="","",IF('Team Scorecard'!B6=0,"No activity logged",IF('Team Scorecard'!D6<20,"Too little data to score fairly yet","Enough data"))) | L6: =IF($A6="","",IF(H6<5,"Compliance first: messages were sent over the 300-character limit.",IF(C6<10,"Targeting: acceptance is well below benchmark. Fix who is being approached and the personal line.",IF(D6<10,"Message quality: people accept but do not reply. Rewrite the opening message.",IF(F6<10,"Conversion: replies are not turning into meetings. Work on the ask and the follow-through.",IF(B6<8,"Lead quality: the prospects being researched score low on fit. Tighten the Sales Navigator filters.","Nothing structural - keep going and raise the volume gradually."))))))
A7: =IF('START HERE'!$B$58="","",'START HERE'!$B$58) | B7: =IF($A7="","",ROUND(IFERROR(AVERAGEIFS('LinkedIn Outreach'!$AA$5:$AA$1203,'LinkedIn Outreach'!$B$5:$B$1203,$A7,'LinkedIn Outreach'!$AA$5:$AA$1203,">0"),0)/100*15,1)) | C7: =IF($A7="","",ROUND(MIN(1,IFERROR('Team Scorecard'!F7/0.3,0))*20,1)) | D7: =IF($A7="","",ROUND(MIN(1,IFERROR('Team Scorecard'!I7/0.15,0))*20,1)) | E7: =IF($A7="","",ROUND(MIN(1,IFERROR('Team Scorecard'!H7/MAX(1,'Team Scorecard'!G7)/0.2,0))*10,1)) | F7: =IF($A7="","",ROUND(MIN(1,(COUNTIFS('LinkedIn Outreach'!$B$5:$B$1203,$A7,'LinkedIn Outreach'!$AC$5:$AC$1203,"6 Meeting / Application")+COUNTIFS('LinkedIn Outreach'!$B$5:$B$1203,$A7,'LinkedIn Outreach'!$AC$5:$AC$1203,"7 Certification / Enterprise opportunity"))/5)*20,1)) | G7: =IF($A7="","",ROUND(MIN(1,COUNTIFS('LinkedIn Outreach'!$B$5:$B$1203,$A7,'LinkedIn Outreach'!$AC$5:$AC$1203,"7 Certification / Enterprise opportunity")/3)*10,1)) | H7: =IF($A7="","",MAX(0,5-'Team Scorecard'!O7*2.5)) | I7: =IF($A7="","",ROUND(SUM(B7:H7),1)) | J7: =IF($A7="","",IF(I7>=80,"A - excellent",IF(I7>=65,"B - solid",IF(I7>=50,"C - needs coaching",IF(I7>=30,"D - at risk","E - not working"))))) | K7: =IF($A7="","",IF('Team Scorecard'!B7=0,"No activity logged",IF('Team Scorecard'!D7<20,"Too little data to score fairly yet","Enough data"))) | L7: =IF($A7="","",IF(H7<5,"Compliance first: messages were sent over the 300-character limit.",IF(C7<10,"Targeting: acceptance is well below benchmark. Fix who is being approached and the personal line.",IF(D7<10,"Message quality: people accept but do not reply. Rewrite the opening message.",IF(F7<10,"Conversion: replies are not turning into meetings. Work on the ask and the follow-through.",IF(B7<8,"Lead quality: the prospects being researched score low on fit. Tighten the Sales Navigator filters.","Nothing structural - keep going and raise the volume gradually."))))))
A8: =IF('START HERE'!$B$59="","",'START HERE'!$B$59) | B8: =IF($A8="","",ROUND(IFERROR(AVERAGEIFS('LinkedIn Outreach'!$AA$5:$AA$1203,'LinkedIn Outreach'!$B$5:$B$1203,$A8,'LinkedIn Outreach'!$AA$5:$AA$1203,">0"),0)/100*15,1)) | C8: =IF($A8="","",ROUND(MIN(1,IFERROR('Team Scorecard'!F8/0.3,0))*20,1)) | D8: =IF($A8="","",ROUND(MIN(1,IFERROR('Team Scorecard'!I8/0.15,0))*20,1)) | E8: =IF($A8="","",ROUND(MIN(1,IFERROR('Team Scorecard'!H8/MAX(1,'Team Scorecard'!G8)/0.2,0))*10,1)) | F8: =IF($A8="","",ROUND(MIN(1,(COUNTIFS('LinkedIn Outreach'!$B$5:$B$1203,$A8,'LinkedIn Outreach'!$AC$5:$AC$1203,"6 Meeting / Application")+COUNTIFS('LinkedIn Outreach'!$B$5:$B$1203,$A8,'LinkedIn Outreach'!$AC$5:$AC$1203,"7 Certification / Enterprise opportunity"))/5)*20,1)) | G8: =IF($A8="","",ROUND(MIN(1,COUNTIFS('LinkedIn Outreach'!$B$5:$B$1203,$A8,'LinkedIn Outreach'!$AC$5:$AC$1203,"7 Certification / Enterprise opportunity")/3)*10,1)) | H8: =IF($A8="","",MAX(0,5-'Team Scorecard'!O8*2.5)) | I8: =IF($A8="","",ROUND(SUM(B8:H8),1)) | J8: =IF($A8="","",IF(I8>=80,"A - excellent",IF(I8>=65,"B - solid",IF(I8>=50,"C - needs coaching",IF(I8>=30,"D - at risk","E - not working"))))) | K8: =IF($A8="","",IF('Team Scorecard'!B8=0,"No activity logged",IF('Team Scorecard'!D8<20,"Too little data to score fairly yet","Enough data"))) | L8: =IF($A8="","",IF(H8<5,"Compliance first: messages were sent over the 300-character limit.",IF(C8<10,"Targeting: acceptance is well below benchmark. Fix who is being approached and the personal line.",IF(D8<10,"Message quality: people accept but do not reply. Rewrite the opening message.",IF(F8<10,"Conversion: replies are not turning into meetings. Work on the ask and the follow-through.",IF(B8<8,"Lead quality: the prospects being researched score low on fit. Tighten the Sales Navigator filters.","Nothing structural - keep going and raise the volume gradually."))))))
A9: =IF('START HERE'!$B$60="","",'START HERE'!$B$60) | B9: =IF($A9="","",ROUND(IFERROR(AVERAGEIFS('LinkedIn Outreach'!$AA$5:$AA$1203,'LinkedIn Outreach'!$B$5:$B$1203,$A9,'LinkedIn Outreach'!$AA$5:$AA$1203,">0"),0)/100*15,1)) | C9: =IF($A9="","",ROUND(MIN(1,IFERROR('Team Scorecard'!F9/0.3,0))*20,1)) | D9: =IF($A9="","",ROUND(MIN(1,IFERROR('Team Scorecard'!I9/0.15,0))*20,1)) | E9: =IF($A9="","",ROUND(MIN(1,IFERROR('Team Scorecard'!H9/MAX(1,'Team Scorecard'!G9)/0.2,0))*10,1)) | F9: =IF($A9="","",ROUND(MIN(1,(COUNTIFS('LinkedIn Outreach'!$B$5:$B$1203,$A9,'LinkedIn Outreach'!$AC$5:$AC$1203,"6 Meeting / Application")+COUNTIFS('LinkedIn Outreach'!$B$5:$B$1203,$A9,'LinkedIn Outreach'!$AC$5:$AC$1203,"7 Certification / Enterprise opportunity"))/5)*20,1)) | G9: =IF($A9="","",ROUND(MIN(1,COUNTIFS('LinkedIn Outreach'!$B$5:$B$1203,$A9,'LinkedIn Outreach'!$AC$5:$AC$1203,"7 Certification / Enterprise opportunity")/3)*10,1)) | H9: =IF($A9="","",MAX(0,5-'Team Scorecard'!O9*2.5)) | I9: =IF($A9="","",ROUND(SUM(B9:H9),1)) | J9: =IF($A9="","",IF(I9>=80,"A - excellent",IF(I9>=65,"B - solid",IF(I9>=50,"C - needs coaching",IF(I9>=30,"D - at risk","E - not working"))))) | K9: =IF($A9="","",IF('Team Scorecard'!B9=0,"No activity logged",IF('Team Scorecard'!D9<20,"Too little data to score fairly yet","Enough data"))) | L9: =IF($A9="","",IF(H9<5,"Compliance first: messages were sent over the 300-character limit.",IF(C9<10,"Targeting: acceptance is well below benchmark. Fix who is being approached and the personal line.",IF(D9<10,"Message quality: people accept but do not reply. Rewrite the opening message.",IF(F9<10,"Conversion: replies are not turning into meetings. Work on the ask and the follow-through.",IF(B9<8,"Lead quality: the prospects being researched score low on fit. Tighten the Sales Navigator filters.","Nothing structural - keep going and raise the volume gradually."))))))
A10: =IF('START HERE'!$B$61="","",'START HERE'!$B$61) | B10: =IF($A10="","",ROUND(IFERROR(AVERAGEIFS('LinkedIn Outreach'!$AA$5:$AA$1203,'LinkedIn Outreach'!$B$5:$B$1203,$A10,'LinkedIn Outreach'!$AA$5:$AA$1203,">0"),0)/100*15,1)) | C10: =IF($A10="","",ROUND(MIN(1,IFERROR('Team Scorecard'!F10/0.3,0))*20,1)) | D10: =IF($A10="","",ROUND(MIN(1,IFERROR('Team Scorecard'!I10/0.15,0))*20,1)) | E10: =IF($A10="","",ROUND(MIN(1,IFERROR('Team Scorecard'!H10/MAX(1,'Team Scorecard'!G10)/0.2,0))*10,1)) | F10: =IF($A10="","",ROUND(MIN(1,(COUNTIFS('LinkedIn Outreach'!$B$5:$B$1203,$A10,'LinkedIn Outreach'!$AC$5:$AC$1203,"6 Meeting / Application")+COUNTIFS('LinkedIn Outreach'!$B$5:$B$1203,$A10,'LinkedIn Outreach'!$AC$5:$AC$1203,"7 Certification / Enterprise opportunity"))/5)*20,1)) | G10: =IF($A10="","",ROUND(MIN(1,COUNTIFS('LinkedIn Outreach'!$B$5:$B$1203,$A10,'LinkedIn Outreach'!$AC$5:$AC$1203,"7 Certification / Enterprise opportunity")/3)*10,1)) | H10: =IF($A10="","",MAX(0,5-'Team Scorecard'!O10*2.5)) | I10: =IF($A10="","",ROUND(SUM(B10:H10),1)) | J10: =IF($A10="","",IF(I10>=80,"A - excellent",IF(I10>=65,"B - solid",IF(I10>=50,"C - needs coaching",IF(I10>=30,"D - at risk","E - not working"))))) | K10: =IF($A10="","",IF('Team Scorecard'!B10=0,"No activity logged",IF('Team Scorecard'!D10<20,"Too little data to score fairly yet","Enough data"))) | L10: =IF($A10="","",IF(H10<5,"Compliance first: messages were sent over the 300-character limit.",IF(C10<10,"Targeting: acceptance is well below benchmark. Fix who is being approached and the personal line.",IF(D10<10,"Message quality: people accept but do not reply. Rewrite the opening message.",IF(F10<10,"Conversion: replies are not turning into meetings. Work on the ask and the follow-through.",IF(B10<8,"Lead quality: the prospects being researched score low on fit. Tighten the Sales Navigator filters.","Nothing structural - keep going and raise the volume gradually."))))))
A11: =IF('START HERE'!$B$62="","",'START HERE'!$B$62) | B11: =IF($A11="","",ROUND(IFERROR(AVERAGEIFS('LinkedIn Outreach'!$AA$5:$AA$1203,'LinkedIn Outreach'!$B$5:$B$1203,$A11,'LinkedIn Outreach'!$AA$5:$AA$1203,">0"),0)/100*15,1)) | C11: =IF($A11="","",ROUND(MIN(1,IFERROR('Team Scorecard'!F11/0.3,0))*20,1)) | D11: =IF($A11="","",ROUND(MIN(1,IFERROR('Team Scorecard'!I11/0.15,0))*20,1)) | E11: =IF($A11="","",ROUND(MIN(1,IFERROR('Team Scorecard'!H11/MAX(1,'Team Scorecard'!G11)/0.2,0))*10,1)) | F11: =IF($A11="","",ROUND(MIN(1,(COUNTIFS('LinkedIn Outreach'!$B$5:$B$1203,$A11,'LinkedIn Outreach'!$AC$5:$AC$1203,"6 Meeting / Application")+COUNTIFS('LinkedIn Outreach'!$B$5:$B$1203,$A11,'LinkedIn Outreach'!$AC$5:$AC$1203,"7 Certification / Enterprise opportunity"))/5)*20,1)) | G11: =IF($A11="","",ROUND(MIN(1,COUNTIFS('LinkedIn Outreach'!$B$5:$B$1203,$A11,'LinkedIn Outreach'!$AC$5:$AC$1203,"7 Certification / Enterprise opportunity")/3)*10,1)) | H11: =IF($A11="","",MAX(0,5-'Team Scorecard'!O11*2.5)) | I11: =IF($A11="","",ROUND(SUM(B11:H11),1)) | J11: =IF($A11="","",IF(I11>=80,"A - excellent",IF(I11>=65,"B - solid",IF(I11>=50,"C - needs coaching",IF(I11>=30,"D - at risk","E - not working"))))) | K11: =IF($A11="","",IF('Team Scorecard'!B11=0,"No activity logged",IF('Team Scorecard'!D11<20,"Too little data to score fairly yet","Enough data"))) | L11: =IF($A11="","",IF(H11<5,"Compliance first: messages were sent over the 300-character limit.",IF(C11<10,"Targeting: acceptance is well below benchmark. Fix who is being approached and the personal line.",IF(D11<10,"Message quality: people accept but do not reply. Rewrite the opening message.",IF(F11<10,"Conversion: replies are not turning into meetings. Work on the ask and the follow-through.",IF(B11<8,"Lead quality: the prospects being researched score low on fit. Tighten the Sales Navigator filters.","Nothing structural - keep going and raise the volume gradually."))))))
A12: =IF('START HERE'!$B$63="","",'START HERE'!$B$63) | B12: =IF($A12="","",ROUND(IFERROR(AVERAGEIFS('LinkedIn Outreach'!$AA$5:$AA$1203,'LinkedIn Outreach'!$B$5:$B$1203,$A12,'LinkedIn Outreach'!$AA$5:$AA$1203,">0"),0)/100*15,1)) | C12: =IF($A12="","",ROUND(MIN(1,IFERROR('Team Scorecard'!F12/0.3,0))*20,1)) | D12: =IF($A12="","",ROUND(MIN(1,IFERROR('Team Scorecard'!I12/0.15,0))*20,1)) | E12: =IF($A12="","",ROUND(MIN(1,IFERROR('Team Scorecard'!H12/MAX(1,'Team Scorecard'!G12)/0.2,0))*10,1)) | F12: =IF($A12="","",ROUND(MIN(1,(COUNTIFS('LinkedIn Outreach'!$B$5:$B$1203,$A12,'LinkedIn Outreach'!$AC$5:$AC$1203,"6 Meeting / Application")+COUNTIFS('LinkedIn Outreach'!$B$5:$B$1203,$A12,'LinkedIn Outreach'!$AC$5:$AC$1203,"7 Certification / Enterprise opportunity"))/5)*20,1)) | G12: =IF($A12="","",ROUND(MIN(1,COUNTIFS('LinkedIn Outreach'!$B$5:$B$1203,$A12,'LinkedIn Outreach'!$AC$5:$AC$1203,"7 Certification / Enterprise opportunity")/3)*10,1)) | H12: =IF($A12="","",MAX(0,5-'Team Scorecard'!O12*2.5)) | I12: =IF($A12="","",ROUND(SUM(B12:H12),1)) | J12: =IF($A12="","",IF(I12>=80,"A - excellent",IF(I12>=65,"B - solid",IF(I12>=50,"C - needs coaching",IF(I12>=30,"D - at risk","E - not working"))))) | K12: =IF($A12="","",IF('Team Scorecard'!B12=0,"No activity logged",IF('Team Scorecard'!D12<20,"Too little data to score fairly yet","Enough data"))) | L12: =IF($A12="","",IF(H12<5,"Compliance first: messages were sent over the 300-character limit.",IF(C12<10,"Targeting: acceptance is well below benchmark. Fix who is being approached and the personal line.",IF(D12<10,"Message quality: people accept but do not reply. Rewrite the opening message.",IF(F12<10,"Conversion: replies are not turning into meetings. Work on the ask and the follow-through.",IF(B12<8,"Lead quality: the prospects being researched score low on fit. Tighten the Sales Navigator filters.","Nothing structural - keep going and raise the volume gradually."))))))
A13: =IF('START HERE'!$B$64="","",'START HERE'!$B$64) | B13: =IF($A13="","",ROUND(IFERROR(AVERAGEIFS('LinkedIn Outreach'!$AA$5:$AA$1203,'LinkedIn Outreach'!$B$5:$B$1203,$A13,'LinkedIn Outreach'!$AA$5:$AA$1203,">0"),0)/100*15,1)) | C13: =IF($A13="","",ROUND(MIN(1,IFERROR('Team Scorecard'!F13/0.3,0))*20,1)) | D13: =IF($A13="","",ROUND(MIN(1,IFERROR('Team Scorecard'!I13/0.15,0))*20,1)) | E13: =IF($A13="","",ROUND(MIN(1,IFERROR('Team Scorecard'!H13/MAX(1,'Team Scorecard'!G13)/0.2,0))*10,1)) | F13: =IF($A13="","",ROUND(MIN(1,(COUNTIFS('LinkedIn Outreach'!$B$5:$B$1203,$A13,'LinkedIn Outreach'!$AC$5:$AC$1203,"6 Meeting / Application")+COUNTIFS('LinkedIn Outreach'!$B$5:$B$1203,$A13,'LinkedIn Outreach'!$AC$5:$AC$1203,"7 Certification / Enterprise opportunity"))/5)*20,1)) | G13: =IF($A13="","",ROUND(MIN(1,COUNTIFS('LinkedIn Outreach'!$B$5:$B$1203,$A13,'LinkedIn Outreach'!$AC$5:$AC$1203,"7 Certification / Enterprise opportunity")/3)*10,1)) | H13: =IF($A13="","",MAX(0,5-'Team Scorecard'!O13*2.5)) | I13: =IF($A13="","",ROUND(SUM(B13:H13),1)) | J13: =IF($A13="","",IF(I13>=80,"A - excellent",IF(I13>=65,"B - solid",IF(I13>=50,"C - needs coaching",IF(I13>=30,"D - at risk","E - not working"))))) | K13: =IF($A13="","",IF('Team Scorecard'!B13=0,"No activity logged",IF('Team Scorecard'!D13<20,"Too little data to score fairly yet","Enough data"))) | L13: =IF($A13="","",IF(H13<5,"Compliance first: messages were sent over the 300-character limit.",IF(C13<10,"Targeting: acceptance is well below benchmark. Fix who is being approached and the personal line.",IF(D13<10,"Message quality: people accept but do not reply. Rewrite the opening message.",IF(F13<10,"Conversion: replies are not turning into meetings. Work on the ask and the follow-through.",IF(B13<8,"Lead quality: the prospects being researched score low on fit. Tighten the Sales Navigator filters.","Nothing structural - keep going and raise the volume gradually."))))))
A15: HOW THE SCORE IS BUILT - and why there is no 'messages sent' component. Lead quality 15, acceptance rate 20, reply rate 20, positive replies 10, meetings and applications 20, downstream conversions 10, compliance 5. Acceptance is scored against the 30% benchmark and reply rate against 15%, both from the Benchmarks tab. Sending more messages cannot raise any of these; sending worse messages to worse-fitting people lowers almost all of them. The Activity gate column exists so that nobody is graded on twenty data points - below 20 connection requests it says so instead of pretending the score is meaningful.

Sheet Team Scorecard
A1: TEAM SCORECARD — one row per employee, updates itself
A2: This is the page to use for one-to-ones and appraisals. Names come from the roster on START HERE; figures come from the log tabs.
A3: Employee | B3: Days logged | C3: Leads researched | D3: Connections sent | E3: Accepted | F3: Acceptance % | G3: Messages sent | H3: Positive replies | I3: Reply % | J3: Meetings booked | K3: Posts published | L3: Community actions | M3: Partner / PR contacts | N3: Engagements | O3: Msgs over 300 chars | P3: Blocked items | Q3: Verdict | R3: Tasks owned | S3: Tasks complete | T3: Task completion | U3: Platforms owned live | V3: Content published
A4: =IF('START HERE'!$B$55="","",'START HERE'!$B$55) -> Employee 1 | B4: =IF($A4="","",IFERROR(SUMPRODUCT(('DAILY ENTRY'!$B$7:$B$1203=$A4)*('DAILY ENTRY'!$A$7:$A$1203<>"")/COUNTIFS('DAILY ENTRY'!$A$7:$A$1203,'DAILY ENTRY'!$A$7:$A$1203&"",'DAILY ENTRY'!$B$7:$B$1203,'DAILY ENTRY'!$B$7:$B$1203&"")),0)) -> 0 | C4: =IF($A4="","",SUMIFS('DAILY ENTRY'!$F$7:$F$1203,'DAILY ENTRY'!$D$7:$D$1203,"Lead researched (Sales Navigator)",'DAILY ENTRY'!$B$7:$B$1203,$A4)) -> 0 | D4: =IF($A4="","",COUNTIFS('LinkedIn Outreach'!$B$5:$B$1203,$A4,'LinkedIn Outreach'!$M$5:$M$1203,"Yes")) -> 0 | E4: =IF($A4="","",COUNTIFS('LinkedIn Outreach'!$B$5:$B$1203,$A4,'LinkedIn Outreach'!$N$5:$N$1203,"Yes")) -> 0 | F4: =IF($A4="","",IFERROR(E4/D4,"")) | G4: =IF($A4="","",COUNTIFS('LinkedIn Outreach'!$B$5:$B$1203,$A4,'LinkedIn Outreach'!$R$5:$R$1203,"Yes")) -> 0 | H4: =IF($A4="","",COUNTIFS('LinkedIn Outreach'!$B$5:$B$1203,$A4,'LinkedIn Outreach'!$S$5:$S$1203,"Interested")+COUNTIFS('LinkedIn Outreach'!$B$5:$B$1203,$A4,'LinkedIn Outreach'!$S$5:$S$1203,"Info Requested")+COUNTIFS('LinkedIn Outreach'!$B$5:$B$1203,$A4,'LinkedIn Outreach'!$S$5:$S$1203,"Meeting Booked")+COUNTIFS('LinkedIn Outreach'!$B$5:$B$1203,$A4,'LinkedIn Outreach'!$S$5:$S$1203,"Converted")) -> 0 | I4: =IF($A4="","",IFERROR(H4/G4,"")) | J4: =IF($A4="","",COUNTIFS('LinkedIn Outreach'!$B$5:$B$1203,$A4,'LinkedIn Outreach'!$S$5:$S$1203,"Meeting Booked")) -> 0 | K4: =IF($A4="","",SUMIFS('DAILY ENTRY'!$F$7:$F$1203,'DAILY ENTRY'!$D$7:$D$1203,"Post / content published",'DAILY ENTRY'!$B$7:$B$1203,$A4)) -> 0 | L4: =IF($A4="","",SUMIFS('DAILY ENTRY'!$F$7:$F$1203,'DAILY ENTRY'!$D$7:$D$1203,"Community answer or comment",'DAILY ENTRY'!$B$7:$B$1203,$A4)) -> 0 | M4: =IF($A4="","",SUMIFS('DAILY ENTRY'!$F$7:$F$1203,'DAILY ENTRY'!$D$7:$D$1203,"Partnership / PR contact",'DAILY ENTRY'!$B$7:$B$1203,$A4)) -> 0 | N4: =IF($A4="","",SUMIFS('DAILY ENTRY'!$F$7:$F$1203,'DAILY ENTRY'!$D$7:$D$1203,"Engagement (commented on someone else)",'DAILY ENTRY'!$B$7:$B$1203,$A4)) -> 0 | O4: =IF($A4="","",COUNTIFS('LinkedIn Outreach'!$B$5:$B$1203,$A4,'LinkedIn Outreach'!$Q$5:$Q$1203,">300")) -> 0 | P4: =IF($A4="","",COUNTIFS('DAILY ENTRY'!$B$7:$B$1203,$A4,'DAILY ENTRY'!$I$7:$I$1203,"Blocked")) -> 0 | Q4: =IF($A4="","",IF(AND(B4=0,D4=0),"No activity logged yet",IF(O4>0,"BREACH: sent messages over the 300-character limit - review the message text",IF(AND(D4>=20,F4<0.2),"Acceptance below 20% - fix targeting or the connection note before sending more",IF(AND(G4>=20,I4<0.1),"Reply rate below the 10% average - the message needs rewriting, not more volume",IF(AND(F4>=0.3,I4>=0.15),"Strong: both acceptance and reply rate are above benchmark",IF(AND(B4>0,D4=0),"Logging daily work but no LinkedIn outreach recorded","Within normal range - compare against the Benchmarks tab"))))))) -> No activity logged yet | R4: =IF($A4="","",COUNTIF('Master Tasks'!$I$4:$I$66,$A4)) -> 0 | S4: =IF($A4="","",COUNTIFS('Master Tasks'!$I$4:$I$66,$A4,'Master Tasks'!$J$4:$J$66,"Complete")) -> 0 | T4: =IF($A4="","",IFERROR(S4/R4,"")) | U4: =IF($A4="","",COUNTIFS('Platform Setup'!$M$4:$M$49,$A4,'Platform Setup'!$J$4:$J$49,"Complete")) -> 0 | V4: =IF($A4="","",COUNTIFS('Content Calendar'!$B$5:$B$403,$A4,'Content Calendar'!$J$5:$J$403,"Published")+COUNTIFS('Content Calendar'!$B$5:$B$403,$A4,'Content Calendar'!$J$5:$J$403,"Repurposed")) -> 0
A5: =IF('START HERE'!$B$56="","",'START HERE'!$B$56) | B5: =IF($A5="","",IFERROR(SUMPRODUCT(('DAILY ENTRY'!$B$7:$B$1203=$A5)*('DAILY ENTRY'!$A$7:$A$1203<>"")/COUNTIFS('DAILY ENTRY'!$A$7:$A$1203,'DAILY ENTRY'!$A$7:$A$1203&"",'DAILY ENTRY'!$B$7:$B$1203,'DAILY ENTRY'!$B$7:$B$1203&"")),0)) | C5: =IF($A5="","",SUMIFS('DAILY ENTRY'!$F$7:$F$1203,'DAILY ENTRY'!$D$7:$D$1203,"Lead researched (Sales Navigator)",'DAILY ENTRY'!$B$7:$B$1203,$A5)) | D5: =IF($A5="","",COUNTIFS('LinkedIn Outreach'!$B$5:$B$1203,$A5,'LinkedIn Outreach'!$M$5:$M$1203,"Yes")) | E5: =IF($A5="","",COUNTIFS('LinkedIn Outreach'!$B$5:$B$1203,$A5,'LinkedIn Outreach'!$N$5:$N$1203,"Yes")) | F5: =IF($A5="","",IFERROR(E5/D5,"")) | G5: =IF($A5="","",COUNTIFS('LinkedIn Outreach'!$B$5:$B$1203,$A5,'LinkedIn Outreach'!$R$5:$R$1203,"Yes")) | H5: =IF($A5="","",COUNTIFS('LinkedIn Outreach'!$B$5:$B$1203,$A5,'LinkedIn Outreach'!$S$5:$S$1203,"Interested")+COUNTIFS('LinkedIn Outreach'!$B$5:$B$1203,$A5,'LinkedIn Outreach'!$S$5:$S$1203,"Info Requested")+COUNTIFS('LinkedIn Outreach'!$B$5:$B$1203,$A5,'LinkedIn Outreach'!$S$5:$S$1203,"Meeting Booked")+COUNTIFS('LinkedIn Outreach'!$B$5:$B$1203,$A5,'LinkedIn Outreach'!$S$5:$S$1203,"Converted")) | I5: =IF($A5="","",IFERROR(H5/G5,"")) | J5: =IF($A5="","",COUNTIFS('LinkedIn Outreach'!$B$5:$B$1203,$A5,'LinkedIn Outreach'!$S$5:$S$1203,"Meeting Booked")) | K5: =IF($A5="","",SUMIFS('DAILY ENTRY'!$F$7:$F$1203,'DAILY ENTRY'!$D$7:$D$1203,"Post / content published",'DAILY ENTRY'!$B$7:$B$1203,$A5)) | L5: =IF($A5="","",SUMIFS('DAILY ENTRY'!$F$7:$F$1203,'DAILY ENTRY'!$D$7:$D$1203,"Community answer or comment",'DAILY ENTRY'!$B$7:$B$1203,$A5)) | M5: =IF($A5="","",SUMIFS('DAILY ENTRY'!$F$7:$F$1203,'DAILY ENTRY'!$D$7:$D$1203,"Partnership / PR contact",'DAILY ENTRY'!$B$7:$B$1203,$A5)) | N5: =IF($A5="","",SUMIFS('DAILY ENTRY'!$F$7:$F$1203,'DAILY ENTRY'!$D$7:$D$1203,"Engagement (commented on someone else)",'DAILY ENTRY'!$B$7:$B$1203,$A5)) | O5: =IF($A5="","",COUNTIFS('LinkedIn Outreach'!$B$5:$B$1203,$A5,'LinkedIn Outreach'!$Q$5:$Q$1203,">300")) | P5: =IF($A5="","",COUNTIFS('DAILY ENTRY'!$B$7:$B$1203,$A5,'DAILY ENTRY'!$I$7:$I$1203,"Blocked")) | Q5: =IF($A5="","",IF(AND(B5=0,D5=0),"No activity logged yet",IF(O5>0,"BREACH: sent messages over the 300-character limit - review the message text",IF(AND(D5>=20,F5<0.2),"Acceptance below 20% - fix targeting or the connection note before sending more",IF(AND(G5>=20,I5<0.1),"Reply rate below the 10% average - the message needs rewriting, not more volume",IF(AND(F5>=0.3,I5>=0.15),"Strong: both acceptance and reply rate are above benchmark",IF(AND(B5>0,D5=0),"Logging daily work but no LinkedIn outreach recorded","Within normal range - compare against the Benchmarks tab"))))))) | R5: =IF($A5="","",COUNTIF('Master Tasks'!$I$4:$I$66,$A5)) | S5: =IF($A5="","",COUNTIFS('Master Tasks'!$I$4:$I$66,$A5,'Master Tasks'!$J$4:$J$66,"Complete")) | T5: =IF($A5="","",IFERROR(S5/R5,"")) | U5: =IF($A5="","",COUNTIFS('Platform Setup'!$M$4:$M$49,$A5,'Platform Setup'!$J$4:$J$49,"Complete")) | V5: =IF($A5="","",COUNTIFS('Content Calendar'!$B$5:$B$403,$A5,'Content Calendar'!$J$5:$J$403,"Published")+COUNTIFS('Content Calendar'!$B$5:$B$403,$A5,'Content Calendar'!$J$5:$J$403,"Repurposed"))
