Workbook

Sheet START HERE
A1: PCI AI — PROJECT CONTROLS INSTITUTE | EMPLOYEE EXECUTION TRACKER
A2: ◀ MAP | B2: Read this page first. It takes 5 minutes and explains exactly how to use every tab.
A3: NEW HERE? Read this page, then TEAM GUIDE (where to log what), then PLATFORM GUIDE (how to use each platform). · A word you do not know? The GLOSSARY tab. Lost? The MAP tab lists every sheet with one click. · Need something to write? Article Bank.
A4: 1. HOW THIS WORKS — employees fill in ONE sheet
A5: EVERY DAY -> DAILY ENTRY tab | B5: This is the only sheet you must fill in. One row for each thing you did: the date, your name, which platform, what kind of work, how many, how long it took and a link that proves it. Every row also carries the two tag columns (Objective + For (brand)); six of the twelve columns are dropdowns, so most of a row is clicking, not typing.
A6: Log as you go, not at 5pm | B6: Add the row when you finish the task. Ten rows a day is normal. If you did nothing on a platform, there is simply no row for it.
A7: ALSO, if you do LinkedIn outreach | B7: The LinkedIn Outreach tab holds one row per PERSON you contact - name, company, the message you sent, and what they replied. This cannot be collapsed into daily totals, because acceptance and reply rates need to be tracked per person.
A8: Everything else fills itself in | B8: Platform Progress, Who Did What, Team Scorecard, Weekly Review, Dashboard and Summary all calculate from what you enter. You never type a number twice. The Daily Log tab is optional.
A9: BEFORE YOU START -> Platform Setup tab | B9: Work through the account list and follow the setup steps written in each row. Mark Status = Complete only when the profile is fully filled in with logo, bio, link and 2FA.
A10: BEFORE YOU WRITE -> Publishing Plan tab | B10: The ten publishing platforms, ranked, with the rule for each one. Read the rule before you publish anywhere.
A11: BEFORE YOU MESSAGE -> Message Bank tab | B11: Never write outreach from scratch. Copy the approved message and replace every [bracket] with real details from the person's profile.
A12: EVERY FRIDAY -> Weekly Review tab | B12: Write your wins, misses and next week's focus. The numbers are already there. Use the dropdown in cell B2 to see just your own week.
A13: REFERENCE -> How-To Guides, LinkedIn Playbook, Benchmarks | B13: Read these when you start a platform for the first time or when you want to know what good looks like.
A14: FOR THE MANAGER -> Weekly Pulse, Objective Performance, Team Scorecard, Dashboard, Summary | B14: Read-only pages — nobody types in them. Monday, in this order: WEEKLY PULSE (what moved last week, green or red) → OBJECTIVE PERFORMANCE (which campaigns earned their hours: compare Value rank with Share of minutes) → TEAM SCORECARD column Q (the one-sentence verdict per person) → DASHBOARD section 9 DATA HEALTH (every number there must read zero before you quote anything to anyone). SUMMARY is the one page to forward upwards.
A15: Master Tasks tab | B15: The full workstream list with an Owner column. Update Status and Progress when a task moves.
A17: 2. TEAM SETTINGS — the manager fills these once (yellow cells)
A18: Team / department name
A19: Manager / reviewer | C19: Required — the manager runs the Monday review and signs QA.
A20: Programme start date (a Monday) | B20: 46251
A21: Working days per week | B21: 5
A22: Our week starts on (1 = Sunday, 2 = Monday) | B22: 2 | C22: Set 1 for a Sunday-Thursday working week (Saudi, Qatar, Kuwait, Bahrain) so Sunday's output lands in the right week. Weekly Pulse and Weekly Review both follow this.
A23: 3. DAILY TARGETS — per person, per working day. The Dashboard multiplies by the number of people on the roster.
A24: Activity | B24: Target per day (each person) | C24: Target per week (auto)
A25: Sales Navigator leads researched | B25: 30 | C25: =B25*'START HERE'!$B$21 -> 150
A26: Connection requests sent | B26: 20 | C26: =B26*'START HERE'!$B$21 -> 100
A27: First messages sent (accepted connections) | B27: 15 | C27: =B27*'START HERE'!$B$21 -> 75
A28: Follow-up messages sent | B28: 10 | C28: =B28*'START HERE'!$B$21 -> 50
A29: Posts published (all platforms) | B29: 2 | C29: =B29*'START HERE'!$B$21 -> 10
A30: Community answers / comments (incl. engagement; 3-5 full answers/week) | B30: 3 | C30: =B30*'START HERE'!$B$21 -> 15
A31: Partnership / PR contacts approached | B31: 5 | C31: =B31*'START HERE'!$B$21 -> 25
A32: Meaningful engagements (likes + comments on others) | B32: 15 | C32: =B32*'START HERE'!$B$21 -> 75
A34: 4. GOLDEN RULES — these protect PCI's reputation. Breaking them is a serious issue.
A35: 1. Be honest. Never tell anyone they have been awarded, approved or guaranteed an honorary certification. You are inviting them to be considered and sharing the criteria — nothing more.
A36: 2. Never invent facts about PCI — numbers of members, accreditations, recognition or partnerships. If you are unsure, ask your manager before you send.
A37: 3. Personalise every message. Read the profile first and reference something real (their role, employer, project type or years of experience).
A38: 4. Keep outreach messages under 300 characters and connection notes under 200 characters.
A39: 5. No bulk sending, no automation tools, no bots, no scraping. LinkedIn restricts accounts for this and it destroys reply rates.
A40: 6. Respect limits: stop at the daily target. If LinkedIn shows a warning, stop for the day and tell your manager.
A41: 7. If someone says no or asks you to stop, thank them politely and never contact them again. Mark Outcome = Declined.
A42: 8. Answer the question first, promote PCI second. On Quora, Reddit and groups a useful answer with no link beats a link with no value.
...

Sheet MAP
A1: MAP — what every tab is for, and what you do on it
A2: Click a name in the first column to jump straight there; every sheet has a ◀ MAP link to come back. Read the WHO TYPES ON IT column before you touch a sheet — most of this workbook calculates itself and is not meant to be typed in. New here? START HERE, then TEAM GUIDE, then PLATFORM GUIDE.
A3: ◀ START HERE
A4: Sheet (click to open) | B4: What this sheet is | C4: Who types on it | D4: What you do here, and when
A5: READ FIRST — what a new joiner reads, in this order
A6: START HERE | B6: The rulebook. It sets out how the team works: what to log, the daily targets everyone is measured against, the golden rules that protect PCI's reputation, the team roster and the five web domains we own. | C6: Manager fills the yellow settings once | D6: Read it end to end on your first day — it takes about five minutes. Come back whenever you are unsure what a rule actually says.
A7: TEAM GUIDE | B7: The onboarding sheet. It answers the one question everyone asks — 'I just did this thing, where do I log it?' — for every kind of work, and explains how your score is calculated. | C7: Nobody — read it | D7: Read it after START HERE. Keep it open for your first week; the 'where do I log what' table settles almost every question.
A8: GROWTH PLAYBOOK | B8: The 23 growth techniques PCI actually uses, each written out in working detail: why it works, the exact steps, how often, and the number that proves it worked. | C8: Nobody — read it | D8: Read the technique before you start that kind of work. It also lists what NOT to do — tactics that get accounts penalised.
A9: PLATFORM GUIDE | B9: One row for every platform we are on, saying what to do there each week, how often, and the single number that proves it is working. Setting the account up is on Platform Setup; this is what you do once it exists. | C9: Nobody — read it | D9: Look up your platform before your first session on it. Gold rows are the highest-value platforms — if time is short, work down from the top.
A10: PR & Target Directory | B10: The named routes out: which publications accept contributed articles, which podcasts take guests, which boards and directories are worth applying to — and which ones we have deliberately decided to skip, with the reason. | C10: Manager only | D10: Check it before you approach anyone. If a route is marked as a skip, do not spend time on it.
A11: Glossary | B11: Every term this workbook uses without stopping to explain it — ICP, canonical link, dwell time, EVM, person-day — in plain English, grouped by where you meet the word. | C11: Nobody — read it | D11: Look a word up the moment it stops you. If a term is missing, say so in the Monday review.
A12: UPGRADE NOTES | B12: The changelog. Every change made to this workbook, what was tested, what was found and what was fixed. | C12: Nobody — read it | D12: Read it when the file changes, so you know what moved and why.
A14: DAILY WORK — the sheets you type on
A15: DAILY ENTRY | B15: The one sheet everybody fills in. One row for each thing you do: the date, your name, which platform, what kind of work, how many, how long it took, and a link that proves it. Every management page in the file is built from these rows. | C15: Everyone | D15: Add the row when you FINISH the task, not at 5pm. Ten rows a day is normal. Set both tags — Objective and For (brand) — on every row.
A16: LinkedIn Outreach | B16: One row per PERSON you contact on LinkedIn. It carries the lead from research through the connection request, the message, the reply and the meeting to the sale. This is the honorary-certification engine. | C16: Everyone | D16: Fill columns A-L when you research the lead, M-T when you send and hear back, AD onward only if it becomes a meeting or a sale. Column AN warns you if the person is already in the sheet.
A17: Partnership Pipeline | B17: One row per ORGANISATION rather than per person: associations, universities, employers and training partners, from first contact to a signed agreement. | C17: Everyone | D17: Open a row when you first approach them. A deal only counts as revenue once a real contract-signed date is in the sheet.
A18: Content Calendar | B18: Every piece of content, from the idea to the published URL and the numbers it produced — impressions, engagements, clicks and leads. | C18: Everyone | D18: Add a row when you plan the piece; set Status to Published AND fill the published date on the day it goes live. Missing either one breaks the reporting.
A19: Content Scheduler | B19: One row per running schedule — a platform, at a cadence, between two dates. It works out how many posts that schedule promised and how many actually went out, so you can see which schedules are slipping. | C19: Everyone | D19: Set one up when you commit to a cadence. Coverage under 100% means you are behind on that schedule. The table below the grid says which platforms can schedule natively and with what limits.
A20: Community & PR | B20: Everywhere you show up as a helpful expert rather than a seller: forum answers, community threads, press mentions, podcast appearances and journalist requests. | C20: Everyone | D20: One row per thread started or substantive answer given — never one per like or one-line comment.
A21: Job Postings | B21: Every open PCI role, on every board it is posted to. One row per platform per position, with the applicant count. | C21: Everyone | D21: Add a row each time you post a role somewhere. Update the applicant count when you check the board.
A22: Link Building | B22: Off-page SEO in one place: every site we want a link from, who we contacted, what we offered, and whether the link actually went live. | C22: Everyone | D22: One row per prospect. Fill the date-live column only when you can see the link on the page — that is what the weekly backlink number counts.
A23: Experiments | B23: A/B tests written down honestly: what you changed, what you expected, what happened, and what you will do about it. | C23: Everyone | D23: Start a row before you run the test, not after. Record the result even when it is disappointing — that is the point of the sheet.
A24: UTM Builder | B24: Builds the tracked links we share. A link without one of these tags is invisible in analytics, so nobody can tell where an enquiry came from. | C24: Everyone | D24: Build the link here first, then paste it into the post. Never share a bare URL in a campaign.
A25: SEO Clusters | B25: The seven big subjects we intend to own in Google. Each has one long pillar page and the supporting articles that link up to it, with the Search Console numbers beside them. | C25: Whoever owns SEO | D25: Use it to see how a piece of content fits the plan before you write it. Column F gives the Article Bank ID of the brief for each supporting article.
A26: Keyword Plan | B26: 76 researched search terms, graded Easy, Medium or Hard from what actually ranks today, with the ten to attack first and the reason each one was chosen. | C26: Whoever owns SEO | D26: Pick your next article from here, Easy first — a new site does not beat PMI or AACE on a hard term. Column P gives the Article Bank ID of its brief.
... A28: Daily Log | B28: An optional one-line-per-day summary. Everything on it is calculated from DAILY ENTRY, so it is a convenience, not a second place to type. | C28: Nobody — it calculates | D28: Ignore it unless you like a daily digest. Nothing depends on it.
A30: RESULTS — read-only pages. Nobody types on these
A31: Weekly Pulse | B31: This week against last week, and against the average of the four completed weeks before it. Green means up, red means down. | C31: Nobody — it calculates | D31: The manager's first stop on Monday. If a high-value effort is falling week on week, rebalance before month-end.
A32: Dashboard | B32: The cumulative record — everything achieved since the programme started, with headline KPI tiles down the right-hand side and a DATA HEALTH block at the bottom that counts logging mistakes. | C32: Nobody — it calculates | D32: Check DATA HEALTH before quoting any number on this page to anyone. Every figure in that block should read zero.
A33: Summary | B33: One page, readable in sixty seconds: the six numbers that matter, volume delivered, what needs a decision, and the daily rhythm expected of the team. | C33: Nobody — it calculates | D33: This is the page to forward upwards. Print it for a board or investor update.
A34: Objective Performance | B34: The same results split two ways: by campaign (honorary outreach, certification sales, authority building…) and by brand (the institute, each certification, PCI World, Certuvo). It also shows minutes per person per campaign. | C34: Nobody — it calculates | D34: Compare Value rank against Share of minutes. If the highest-value campaigns are getting the smallest share of the team's hours, move people.
A35: Team Scorecard | B35: Every person's outreach numbers side by side — volume, acceptance rate, reply rate, meetings — with a one-sentence verdict per person. | C35: Nobody — it calculates | D35: Read column Q first: it says in plain words what each person should fix.
A36: Employee Score | B36: The weighted score out of 100 used in reviews. Quality counts far more than volume, and no score appears until there is enough history to be fair. | C36: Nobody — it calculates | D36: Look at the 'What to fix first' column, not just the number. A blank grade means not enough data yet, not a bad result.
A37: Weekly Review | B37: The Friday page: what went well, what did not, and next week's focus, with the week's numbers already filled in beside your notes. | C37: Everyone writes their own notes | D37: Fill it in every Friday. Use the dropdown at the top right to see just your own week.
A38: Platform Progress | B38: How much has actually happened on each of the 133 platforms, how long ago, and who touched it last — set against how valuable that platform is. | C38: Nobody — it calculates | D38: Use it to find neglected high-value platforms. The Attention column tells you which ones have gone quiet.
A39: Who Did What | B39: A grid of every platform against every person, so you can see at a glance who has been carrying which channel. | C39: Nobody — it calculates | D39: Use it when reallocating platforms, or when someone is away and their channels need covering.
A40: Accounts Register | B40: Every account we hold: who owns it, whether two-factor is on, and the reference to the entry in the password manager. | C40: Manager only | D40: Passwords are NEVER stored here — only the vault reference. Check it when somebody joins or leaves.
A42: MANAGEMENT — the manager sets these up
A43: Master Tasks | B43: The full workstream list: every task needed to build the marketing function, with an owner, a due date and what 'done' looks like. | C43: Manager only | D43: Assign an owner and a due date to every row before rollout. Update Status as tasks move.
A44: Platform Setup | B44: All 133 platforms with the steps to create and finish each account, its priority and value rank, which countries it is strongest in, and which brand it serves. | C44: Manager only | D44: Work down it when setting the estate up. Mark Status = Complete only when the profile is genuinely finished — logo, bio, link and two-factor.
...

Sheet TEAM GUIDE
A1: TEAM GUIDE — how this system works, end to end
A2: ◀ MAP | B2: For every team member, new or old. Fifteen minutes here saves the manager explaining the same thing ten times. The deeper references are How-To Guides, LinkedIn Playbook and GROWTH PLAYBOOK.
A4: THE WHOLE SYSTEM IN ONE SENTENCE
A5: You do real marketing work → you log it the same day with evidence → the Dashboard, scorecards and funnel build themselves → the manager reviews Monday morning → next week gets better. Nothing here is busywork: every cell you fill feeds a number a decision is made on.
A7: WHERE DO I LOG WHAT — the only mapping you must memorise
A8: You did this… | B8: Log it here | C8: Also here (if it applies) | D8: It shows up in… | E8: Same-day rule
A9: Researched leads in Sales Navigator | B9: DAILY ENTRY (count + minutes) | C9: LinkedIn Outreach — one row per lead | D9: Team Scorecard, Dashboard §4 | E9: Log before you finish for the day
A10: Sent a connection request / message / follow-up | B10: LinkedIn Outreach — tick the columns on that lead's row | C10: DAILY ENTRY (count for the day) | D10: Funnel, Employee Score | E10: Paste the exact message text
A11: Got a reply / booked a meeting | B11: LinkedIn Outreach — Outcome column | C11: — | D11: Funnel stages 5–6, Dashboard §3 | E11: Update the same day; add Meeting date
A12: Published a post / article / video | B12: Content Calendar — one row per item | C12: DAILY ENTRY (count) | D12: Dashboard §5, Publishing Plan | E12: Paste the published URL
A13: Answered on Quora / Reddit / a community | B13: Community & PR — one row per answer | C13: DAILY ENTRY (count) | D13: Dashboard §5 | E13: Paste the thread URL
A14: Contacted a partner / university / podcast | B14: Partnership Pipeline — one row per organisation | C14: Community & PR for individual touches | D14: Partnership Pipeline stage, Dashboard §8 | E14: Score ICP fit honestly
A15: Ran an A/B test | B15: Experiments — one row per test | C15: — | D15: Playbook improvements | E15: Conclude before starting the next
A16: Built a tracked link | B16: UTM Builder | C16: — | D16: Google Analytics campaigns | E16: Copy only the generated link
A17: Set up / improved an account | B17: Platform Setup — status + profile % | C17: DAILY ENTRY ('Account created / profile completed') | D17: Accounts Register, Dashboard §2 | E17: Record the vault entry name
A18: Reviewed analytics | B18: DAILY ENTRY (Analytics review) | C18: SEO Clusters for search data | D18: Platform Progress | E18: One row per session, primary tool
A19: Sent an email campaign / WhatsApp / Telegram / SMS broadcast | B19: DAILY ENTRY — 'Email campaign sent' or 'WhatsApp / Telegram / SMS sent', How many = messages delivered | C19: — | D19: Weekly Pulse (email / WhatsApp-SMS rows) | E19: Log the same day with the campaign report link
... A24: EVERY row, whatever it is | B24: Set BOTH tag columns: Objective (which campaign — honorary outreach, a certification's sales, authority building…) and For (brand) (who it is for — the institute, PCL-AI / PFL-AI / PML-AI, PCI World or Certuvo) | C24: — | D24: Objective Performance — results per campaign AND per brand | E24: An untagged row lands in a red '(no objective set)' / '(no brand set)' line the manager reviews Monday
A26: YOUR FIRST DAY (the manager ticks these on START HERE §10)
A27: 1) Read START HERE top to bottom — especially the Golden Rules and the sharing rules (§9).
A28: 2) Check your name is on the roster exactly as you will select it in dropdowns.
A29: 3) Get password-vault access from the manager. Open Accounts Register to see which vault entry each platform uses.
A30: 4) Optimise your own LinkedIn profile using LinkedIn Playbook step A. Do not send anything yet.
A31: 5) Read the Message Bank. You may only ever send rows marked Approved — personalised, never pasted blind.
A32: 6) Log your first 5 researched leads in LinkedIn Outreach and show the manager BEFORE sending any request.
A33: 7) After the manager reviews your first 3 sent messages, you are live. Follow the daily targets from START HERE §3.
A35: YOUR EVERY DAY — the 20-minute logging habit
A36: • Morning (5 min): open Dashboard → 'Follow-ups due today' and your red cells. Clear those first — a due follow-up beats a new lead.
A37: • During the day: work in your platforms. Keep LinkedIn Outreach open; a lead takes 30 seconds to log while the profile is in front of you.
A38: • Before you stop (15 min): fill DAILY ENTRY — one row per activity type, with counts, minutes and one evidence link. If it is not logged today, it did not happen.
... A41: HOW YOUR SCORE WORKS (Employee Score tab — quality beats volume)
A42: Lead quality (15) | B42: Are the leads you research genuinely in-profile (8+ years, right roles)?
A43: Acceptance rate (20) | B43: Do your connection requests get accepted? Benchmark: 30%+ is good. Personalisation drives this.
A44: Reply rate (20) | B44: Do your messages get replies? Fluent copying of the Message Bank with real personalisation drives this.
A45: Positive replies (10) | B45: Interested / info requested / meeting booked.
A46: Meetings & applications (20) | B46: The outcomes that matter.
A47: Downstream results (10) | B47: Conversions attributed to your leads.
A48: Compliance (5) | B48: No over-length messages, no rule breaches. Breaches zero this and flag the manager.
A49: No grade appears until you have ~20 connections of history — a blank grade means 'not enough data yet', not 'failing'.
A51: FREQUENTLY ASKED
...

Sheet GROWTH PLAYBOOK
A1: GROWTH PLAYBOOK — the techniques, in working detail
A2: ◀ MAP | B2: Each technique: why it works, the exact steps, cadence, the number that proves it is working, and the mistake that gets accounts banned or rankings burned. Every step logs into the sheet named in the last column.
A4: Technique | B4: Why it works | C4: Exactly how — numbered steps | D4: Cadence | E4: KPI that proves it | F4: Logs into
A5: 1. SEO content clusters (pillar + spokes) | B5: Google ranks depth, not scattered posts. One pillar page per money topic ('project controls certification', 'earned value management') with 6-10 supporting articles all linking back to it makes PCI the topical authority. | C5: 1) Pick the cluster in SEO Clusters — pillar phrase + 8 supporting questions people search. 2) Write the pillar (2,500+ words, answers the whole topic, cites standards). 3) One supporting article per week answering ONE question, linking UP to the pillar with exact-phrase anchor. 4) Interlink siblings. 5) Add FAQ blocks with the literal question as a heading. 6) Track impressions/clicks/position monthly from Search Console into SEO Clusters. | D5: 1 pillar / month; 1-2 spokes / week | E5: Search Console: position for the pillar phrase; clicks/month | F5: SEO Clusters
A6: 2. E-E-A-T authority signals | B6: Google's quality systems reward demonstrated Experience, Expertise, Authority, Trust — critical for an education brand ranked among established bodies. | C6: 1) Every article carries a named author with credentials and a bio page. 2) Author bios link to their LinkedIn and publications. 3) Cite primary sources (standards, published data) — never invent numbers. 4) Keep an About/Governance page path from every article. 5) Get authors quoted elsewhere (see technique 4) and link those mentions back to the bio. | D6: Continuous — a rule, not a task | E6: Branded-search volume; author-name searches | F6: Content Calendar
A7: 3. Answer-engine optimisation (AEO) — being the cited answer | B7: AI answers (Google AI Overviews, ChatGPT, Perplexity) are a fast-growing discovery surface, and the traffic they send arrives with the question already framed — treat published conversion multiples as vendor marketing until you measure your own in GA4. The pipelines differ: ChatGPT retrieves from Bing's index, Perplexity crawls itself, AI Overviews uses Google — each needs its own work. The pattern that repeats across cited pages is a 2-3 sentence direct answer in the opening. | C7: 1) robots.txt: explicitly allow GPTBot, OAI-SearchBot, PerplexityBot, ClaudeBot, Google-Extended (check the CDN/WAF is not blocking them). 2) Verify the domain in Bing Webmaster Tools + enable IndexNow — that is the ChatGPT pipeline. 3) Restructure the top 30 pages: question-form H2s with a 2-3 sentence answer capsule directly under each, then depth; add FAQ blocks and comparison tables. 4) Put one cited statistic in every major section — and publish original data so PCI becomes the source others cite. 5) Off-page is most of the battle: get PCI named in the pages the engines already cite (certification listicles, Reddit/Quora threads, trade-press roundups) — pitch inclusion into existing ranking articles before writing new ones. 6) Keep entity facts identical across the site, Wikidata, Crunchbase, LinkedIn, GBP. 7) Monthly: run the 20-prompt audit; log which domains get cited; target them. | D7: 5 pages restructured / month + monthly audit | E7: Brand mention rate across 20 prompts; AI-referral sessions in GA4 | F7: SEO Clusters / Experiments
A8: 4. Digital PR & backlink earning (post-HARO stack) | B8: Links and mentions from real publications remain the strongest ranking and AI-citation input. HARO is dead (shut Dec 2024); the working 2026 stack is journalist-request services + contributed articles + podcast guesting + one quarterly data study. | C8: 1) Build a one-page expert kit per spokesperson (bio, credentials, 5 angles, headshot). 2) Subscribe: Source of Sources + Help a B2B Writer (free), Qwoted / Featured, ResponseSource for UK press; monitor #journorequest on X and Bluesky twice daily. 3) Answer only on-expertise queries within 2 hours: 80-120 words, data-led, quote-ready. 4) Publish one original data study per quarter (salary survey, AI-adoption survey) — the single best link magnet — and pitch it to the trade press on the PR & Target Directory tab. 5) One contributed article and one podcast pitch per month from the same tab. 6) Every placement goes on an 'As featured in' page (E-E-A-T + AI-citation asset). 7) Never pay for links; never mass-pitch off-topic — accounts get deprioritised. | D8: 3-5 responses / week; monthly article + podcast; quarterly study | E8: Linked placements / month; referring domains; AI-answer brand mentions | F8: Community & PR
A9: 5. LinkedIn organic engine (2026 mechanics) | B9: The decision-makers are here, but the algorithm has changed: personal profiles reach several times what company pages do on identical content (published estimates cluster around 5-10x; measure your own), document/carousel posts lead engagement, dwell time (15+ seconds of reading) is the top ranking signal, and external links in the post body still suppress reach. | C9: 1) Put 70% of effort behind 2-3 named staff profiles; the company page is the archive/credibility layer that reshares people. 2) Weekly per profile: one document/carousel (exam tips, salary data), one short native video (under 90s), one text story — written for dwell: strong first two lines, line-broken body, a chart screenshot. 3) Comment meaningfully on 15 target-audience posts daily BEFORE posting. 4) Links go in the first comment or profile — never the post body. 5) Reply to every comment within 60 minutes of posting (first-hour velocity gates reach). 6) Reshares from colleagues staggered, not simultaneous — identical simultaneous reposts suppress all copies. 7) Outreach only through the approved message system; never automate — engagement pods and AI-comment tools are detected and reach-penalised. | D9: Daily comments; 3 posts / week / profile; fortnightly newsletter | E9: Member reach per post; acceptance %; reply %; newsletter subscribers | F9: Content Calendar + LinkedIn Outreach
A10: 6. Community-led growth (answer first, never spam) | B10: Quora, Reddit, Planning Planet, PMI Community, Stack Exchange rank in Google for years and reach practitioners directly. One good answer works forever; one spammy answer burns the account and the brand. | C10: 1) Pick 2 communities per person, build real profiles (disclose PCI affiliation). 2) Answer the question COMPLETELY first; PCI gets one contextual mention only where genuinely relevant — max 1 link per 5 answers on Reddit, none on Stack Exchange. 3) Target questions that already rank in Google (search the question first). 4) 3-5 quality answers/week per person beats 20 thin ones. 5) Log every answer in Community & PR with the thread URL. 6) Read each community's self-promotion rules before the first post — bans are permanent. | D10: 3-5 answers / person / week | E10: Answer views, upvotes, referral sessions in GA4 | F10: Community & PR
A11: 7. Syndication waterfall (one asset, many surfaces — canonicals verified) | B11: Every original article can reach several extra audiences without duplicate-content damage — IF each platform's canonical reality is respected. Verified 2026: Medium, DEV and Hashnode support canonicals; Substack and LinkedIn Articles do NOT. | C11: 1) Publish the original on the website first; allow 2-10 days and verify it is indexed before syndicating. 2) Medium: use the Import tool — it sets the canonical to the original automatically. 3) LinkedIn Articles: 300-word excerpt + 'read the full analysis' link — never the full piece (no canonical support). 4) Substack: native newsletter framing + link only — never paste the full post (no canonical; the copy can outrank your site). 5) Slides to SlideShare; a 60-second summary to Shorts; an audio take to the podcast. 6) Each copy = its own Content Calendar row, status Repurposed, linking the original; plan the waterfall in the 'Repurpose to' column at writing time. 7) If a syndicated copy outranks the original, strengthen internal links to the original or request removal. | D11: Top 2 posts / month | E11: Referral sessions per surface; original URL keeps the ranking | F11: Content Calendar / Publishing Plan
A12: 8. Webinar → content engine | B12: One monthly webinar produces the month's best content and the warmest leads: registrants are self-qualified by topic. | C12: 1) Monthly topic from the best-performing cluster. 2) Deliver on Zoom Webinars; list on Eventbrite/Luma/Meetup + LinkedIn Event. 3) UTM every registration link. 4) Replay to YouTube; cut 3-5 Shorts; write the recap article (technique 7 waterfall). 5) Registrants enter the ESP nurture sequence; attendees get the certification next-step email within 24h. 6) Every speaker invitation logged in Partnership Pipeline. | D12: Monthly | E12: Registrants, attendance %, replay views, applications started | F12: Partnership Pipeline + Content Calendar
A13: 9. Email nurture (the owned list) | B13: The only audience no algorithm can take away, and the highest-converting surface for a considered purchase like certification. | C13: 1) One lead magnet per certification (syllabus PDF, formula sheet, salary guide) behind a form. 2) Welcome sequence: 5 emails over 2 weeks — value, value, story, proof, ask. 3) Fortnightly newsletter after that: one insight, one resource, one next step. 4) Every send is one Email Marketing (ESP) row in DAILY ENTRY. 5) Consent only — record lawful basis at capture; unsubscribe honoured same day. | D13: Fortnightly sends; sequences always-on | E13: List growth/month, open %, click %, applications from email | F13: DAILY ENTRY + UTM Builder
A14: 10. Digital badge loop (Credly) | B14: Every certified professional who shares a verifiable badge markets to their whole network with third-party credibility — near-zero cost, compounds with every cohort. | C14: 1) Issue every credential as a Credly badge automatically on conferral. 2) Prompt shares to LinkedIn in the conferral email (one click). 3) Repost great badge-shares from the company page (with permission). 4) Track share-rate; a shared badge is a logged Engagement. | D14: Automatic per conferral; monthly share-rate review | E14: Badge share rate; referral traffic from credly.com | F14: Platform Setup + DAILY ENTRY
A15: 11. Directories, citations & reviews | B15: Consistent entity citations (name-address-site) across credible directories underpin the knowledge panel and AI-engine trust; course directories add referral leads directly. | C15: 1) Complete Google Business Profile + Bing Places with identical details. 2) List courses on findcourses/coursetakers-type aggregators (UK/US/Gulf). 3) CPD directories where factually eligible — never claim accreditation that does not exist. 4) Invite genuinely satisfied certified professionals to Trustpilot — never incentivised, never gated. 5) Keep Crunchbase/Wikidata facts current. | D15: One-time setup + quarterly verification | E15: Citation consistency; referral sessions from directories | F15: Platform Setup + QA & Compliance
... A27: 23. Off-page SEO — the link engine (guardrailed) | B27: Referring domains are the strongest off-page ranking signal a new domain can earn, and for AI engines every credible link is one more corroborating source. This technique turns the linkable assets (research report, tools, guides) into a systematic weekly link programme instead of hoping. | C27: 1) Quarterly competitor backlink gap: list who links to AACE, Project Control Academy, EVMi and projectcontrolsinstitute.com but not to us (free: their public mention SERPs + Ahrefs/Semrush free webmaster tiers on our own domain) — every gap is a prospect row in Link Building. 2) Monthly unlinked-mention reclaim: search the brand names in quotes; every mention without a link gets a polite ask — the easiest links that exist. 3) Resource-page + broken-link outreach: university careers pages, PM resource lists, association link pages — pitch the research report, calculators and guides as the replacement or addition. 4) Every guest post, journalist quote, podcast appearance and directory listing from the other techniques gets its own Link Building row — one system of record for off-page. 5) Anchors natural: brand or bare URL for most links; exact-match keywords sparingly. 6) NEVER: paid links, PBNs, bulk reciprocal swaps, comment/forum spam, fiverr link gigs — that is the link spam Google's SpamBrain demotes, and it burns the domain permanently. 7) Weekly rhythm: 10 new prospects logged, 5 outreach emails, follow-ups cleared; log the day's work in DAILY ENTRY as 'Link building / outreach (off-page)'. | D27: Weekly: 10 prospects, 5 outreach; monthly mention-reclaim; quarterly gap analysis | E27: Referring domains trend (Search Console links report + 'Earned - live' rows) | F27: Link Building

Sheet PLATFORM GUIDE
A1: PLATFORM GUIDE — how to use every platform, step by step
A2: ◀ MAP | B2: One row per platform, the whole estate. Account setup lives on Platform Setup (column E); this sheet is the WEEKLY PLAY once the account exists — what to do, how often, and the number that proves it is working. Identity columns update from Platform Setup automatically. Gold rows are the top-10 value platforms: if time is short, work this sheet top rank first.
A3: Platform | B3: Area | C3: Priority | D3: Value rank | E3: Strongest in (countries) | F3: What it's for (logging rule) | G3: How to use it — step by step | H3: KPI that proves it | I3: Time / week
A4: ='Platform Setup'!$B$4 -> LinkedIn Company Page | B4: ='Platform Setup'!$C$4 -> LinkedIn | C4: ='Platform Setup'!$D$4 -> Critical | D4: ='Platform Setup'!$P$4 -> 1 | E4: ='Platform Setup'!$Q$4 -> Global — the professional default | F4: One row per PAGE post. A reshare from a personal profile is logged on LinkedIn Personal Profile, not here. | G4: 1) 3 posts/week from Content Calendar (carousel, credential story, poll). 2) Reply to every comment within 60 minutes of posting (first-hour velocity gates reach). 3) Reshare each post from personal profiles next morning. 4) Log each post in Content Calendar with URL. | H4: Follower growth + engagement rate per post | I4: 3 h
A5: ='Platform Setup'!$B$5 -> LinkedIn Personal Profile | B5: ='Platform Setup'!$C$5 -> LinkedIn | C5: ='Platform Setup'!$D$5 -> Critical | D5: ='Platform Setup'!$P$5 -> 2 | E5: ='Platform Setup'!$Q$5 -> Global — the professional default | F5: All outreach (connect / message / follow-up) logs here. There is no plain 'LinkedIn'. | G5: 1) Work the daily targets: research leads, send personalised connects, message accepted ones (Message Bank approved text only). A FREE LinkedIn account allows only a handful of personalised connection notes per month — check the current cap on the account before planning the week; Premium/Sales Navigator seats are what make the note-led targets reachable. 2) Work the daily engagement target from START HERE §3 (15 likes + comments on other people's posts), of which at least 5 are substantive comments on prospect posts. 3) Log every touch in LinkedIn Outreach same day. | H5: Acceptance % and reply % (Dashboard §3) | I5: 5 h/day team-wide
A6: ='Platform Setup'!$B$6 -> LinkedIn Sales Navigator | B6: ='Platform Setup'!$C$6 -> LinkedIn | C6: ='Platform Setup'!$D$6 -> Critical | D6: ='Platform Setup'!$P$6 -> 3 | E6: ='Platform Setup'!$Q$6 -> Global — the professional default | F6: Lead research only. | G6: 1) Build one saved search per segment (Lead Segment list). 2) Pull 30 qualified leads/day per person into LinkedIn Outreach with the why-them note. 3) Refresh saved-search alerts each Monday. | H6: Qualified leads logged/day vs target | I6: 1 h/day
A7: ='Platform Setup'!$B$7 -> LinkedIn Articles | B7: ='Platform Setup'!$C$7 -> LinkedIn | C7: ='Platform Setup'!$D$7 -> Critical | D7: ='Platform Setup'!$P$7 -> 4 | E7: ='Platform Setup'!$Q$7 -> Global | F7: Only items made in the Write-article editor. Newsletter issues go to LinkedIn Newsletter. | G7: 1) One article/month per named leader (repurpose a Website/Blog original, canonical to site). 2) 1,200+ words, credential CTA at the end. 3) Log in Content Calendar as Repurposed. | H7: Article views + profile visits | I7: 2 h/month
A8: ='Platform Setup'!$B$8 -> LinkedIn Newsletter | B8: ='Platform Setup'!$C$8 -> LinkedIn | C8: ='Platform Setup'!$D$8 -> High | D8: ='Platform Setup'!$P$8 -> 19 | E8: ='Platform Setup'!$Q$8 -> Global | F8: Newsletter issues win over LinkedIn Articles. | G8: 1) One issue every fortnight from the Company Page. 2) Subject = a question practitioners ask (steal from Keyword Plan Easy queries). 3) End every issue with one credential CTA. | H8: Subscriber growth per issue | I8: 2 h/fortnight
A9: ='Platform Setup'!$B$9 -> LinkedIn Groups | B9: ='Platform Setup'!$C$9 -> LinkedIn | C9: ='Platform Setup'!$D$9 -> High | D9: ='Platform Setup'!$P$9 -> 20 | E9: ='Platform Setup'!$Q$9 -> Global | F9: One row per group discussion started or answered — not per like. | G9: 1) 3 useful answers/week in the 10 joined groups — answer, never pitch. 2) Note engaged members as leads in LinkedIn Outreach. 3) Log in Community & PR. | H9: Answers logged + leads sourced from groups | I9: 1.5 h
A10: ='Platform Setup'!$B$10 -> LinkedIn Live | B10: ='Platform Setup'!$C$10 -> LinkedIn | C10: ='Platform Setup'!$D$10 -> High | D10: ='Platform Setup'!$P$10 -> 21 | E10: ='Platform Setup'!$Q$10 -> Global | F10: Native live video; repurpose to YouTube after. | G10: 1) One live/month: expert interview or exam-prep clinic, promoted 10 days ahead. 2) Multistream via StreamYard to YouTube. 3) Clip 3 shorts from the recording within 48h. | H10: Live viewers + replay views | I10: 4 h/month
A11: ='Platform Setup'!$B$11 -> YouTube | B11: ='Platform Setup'!$C$11 -> Social Media | C11: ='Platform Setup'!$D$11 -> Critical | D11: ='Platform Setup'!$P$11 -> 5 | E11: ='Platform Setup'!$Q$11 -> Global | F11: Shorts are YouTube + Content Type = Short Video. Structure exam-prep playlists as YouTube Courses for the EDU shelf. Vimeo retired. | G11: 1) One long-form/week (webinar cut, expert interview, how-to) + 3 Shorts clipped from it. 2) Titles from Keyword Plan questions; chapters + description links with UTMs. 3) Playlists per certification; exam-prep playlist as a YouTube Course. | H11: Watch time + subscribers; clicks to site (UTM) | I11: 4 h
A12: ='Platform Setup'!$B$12 -> Facebook Page | B12: ='Platform Setup'!$C$12 -> Social Media | C12: ='Platform Setup'!$D$12 -> High | D12: ='Platform Setup'!$P$12 -> 22 | E12: ='Platform Setup'!$Q$12 -> India, SE Asia, MENA — weak for UK/US professionals | F12: One row per page post. Boosting a post is paid media, logged separately. | G12: 1) 3 posts/week mirrored from LinkedIn (reformat, don't cross-post links only). 2) Boost nothing organically weak. 3) Reply to comments/DMs daily — India/MENA audience is active here. | H12: Reach + profile actions | I12: 1 h
A13: ='Platform Setup'!$B$13 -> Instagram | B13: ='Platform Setup'!$C$13 -> Social Media | C13: ='Platform Setup'!$D$13 -> High | D13: ='Platform Setup'!$P$13 -> 23 | E13: ='Platform Setup'!$Q$13 -> Gulf-strong global (KSA 77% penetration) | F13: One row per feed post or Reel. A day's Stories are one row, not one per frame. | G13: 1) 3 posts/week: carousel tips, credential stories, reels from YouTube Shorts. 2) Stories on exam dates/webinars. 3) Bio link via UTM to the current campaign page. Gulf audience is here — use Arabic captions where relevant. | H13: Reach + link taps | I13: 1.5 h
A14: ='Platform Setup'!$B$14 -> X (Twitter) | B14: ='Platform Setup'!$C$14 -> Social Media | C14: ='Platform Setup'!$D$14 -> Medium | D14: ='Platform Setup'!$P$14 -> 48 | E14: ='Platform Setup'!$Q$14 -> US, Japan, KSA (top Arab market) | F14: One row per post or thread — a thread is ONE row, not one per tweet. | G14: 1) One insight post/day + replies in industry conversations. 2) Thread each new article into 5-7 tweets ending with the link. 3) Watch #journorequest daily (technique 4). | H14: Impressions + profile clicks | I14: 1 h
A15: ='Platform Setup'!$B$15 -> Threads | B15: ='Platform Setup'!$C$15 -> Social Media | C15: ='Platform Setup'!$D$15 -> Medium | D15: ='Platform Setup'!$P$15 -> 49 | E15: ='Platform Setup'!$Q$15 -> India, Brazil, US | F15: One row per post. Replies to other people are engagement, logged as 'Engagement (commented on someone else)'. | G15: 1) Mirror the X cadence (1 post/day) — India + US audience. 2) Native text, no link-dumping; link in reply. 3) Engage 5 PM-adjacent threads daily. | H15: Followers + engagement | I15: 30 min
A16: ='Platform Setup'!$B$16 -> TikTok | B16: ='Platform Setup'!$C$16 -> Social Media | C16: ='Platform Setup'!$D$16 -> Medium | D16: ='Platform Setup'!$P$16 -> 50 | E16: ='Platform Setup'!$Q$16 -> KSA + Gulf strongest; global | F16: One row per video published. | G16: 1) 3 educational shorts/week (reuse YouTube Shorts, native captions). 2) Hook in the first 2 seconds: a mistake, a number, a question. 3) KSA/Gulf hashtags — this is a Gulf reach channel. | H16: Views + follows from KSA/Gulf | I16: 1.5 h
A17: ='Platform Setup'!$B$17 -> Pinterest | B17: ='Platform Setup'!$C$17 -> Social Media | C17: ='Platform Setup'!$D$17 -> Low | D17: ='Platform Setup'!$P$17 -> 96 | E17: ='Platform Setup'!$Q$17 -> Global | F17: One row per batch session, not per Pin — record how many Pins in 'How many'. | G17: 1) Pin every infographic/carousel to topic boards monthly (Idea Pins were retired in 2023 — use standard image or video Pins). 2) One checklist Pin per published article. 3) UTM every destination link. | H17: Outbound clicks | I17: 30 min/month
A18: ='Platform Setup'!$B$18 -> Bluesky | B18: ='Platform Setup'!$C$18 -> Social Media | C18: ='Platform Setup'!$D$18 -> Low | D18: ='Platform Setup'!$P$18 -> 97 | E18: ='Platform Setup'!$Q$18 -> US + UK niche | F18: Watching brief; thin project-controls density today. | G18: 1) Watching brief: mirror 2 posts/week. 2) Revisit quarterly — move up only if PM community density appears. | H18: Follower trend (quarterly review) | I18: 15 min
A19: ='Platform Setup'!$B$19 -> Website / Blog | B19: ='Platform Setup'!$C$19 -> Publishing | C19: ='Platform Setup'!$D$19 -> Critical | D19: ='Platform Setup'!$P$19 -> 6 | E19: ='Platform Setup'!$Q$19 -> Global | F19: Originals publish here. Each syndicated copy = own row, Content Status Repurposed. | G19: 1) Publish per Keyword Plan: one spoke/week, Easy difficulty first, mapped in SEO Clusters. 2) Every post: named author, sources, FAQ block, credential CTA, internal links to pillar. 3) Originals here FIRST; syndicate once indexed (2-10 days) with canonical. | H19: Search Console clicks + positions on target keywords | I19: 4 h
A20: ='Platform Setup'!$B$20 -> Medium | B20: ='Platform Setup'!$C$20 -> Publishing | C20: ='Platform Setup'!$D$20 -> High | D20: ='Platform Setup'!$P$20 -> 24 | E20: ='Platform Setup'!$Q$20 -> Global | F20: Syndication surface — set the canonical link. | G20: 1) Republish site originals once indexed (2-10 days) via the Import tool — canonical set automatically. 2) Submit to 1-2 relevant publications. 3) One native answer-style piece/month targeting an Easy question keyword. | H20: Referral visits + follows | I20: 1 h
A21: ='Platform Setup'!$B$21 -> Substack | B21: ='Platform Setup'!$C$21 -> Publishing | C21: ='Platform Setup'!$D$21 -> Medium | D21: ='Platform Setup'!$P$21 -> 51 | E21: ='Platform Setup'!$Q$21 -> Global | F21: Only issues natively published on Substack. | G21: 1) Only if the newsletter lives natively here — otherwise skip (ESP owns email). 2) If used: fortnightly issue, cross-recommend via beehiiv-style recommendations. | H21: Subscriber growth | I21: 2 h/fortnight
A22: ='Platform Setup'!$B$22 -> SlideShare | B22: ='Platform Setup'!$C$22 -> Publishing | C22: ='Platform Setup'!$D$22 -> Medium | D22: ='Platform Setup'!$P$22 -> 52 | E22: ='Platform Setup'!$Q$22 -> Global | F22: One row per deck uploaded. | G22: 1) Upload each deck/one-pager monthly with keyword-rich title + description. 2) Link back to the source page. 3) No bulk dumping. | H22: Views + clickthroughs | I22: 30 min/month
A23: ='Platform Setup'!$B$23 -> WordPress.com | B23: ='Platform Setup'!$C$23 -> Publishing | C23: ='Platform Setup'!$D$23 -> Medium | D23: ='Platform Setup'!$P$23 -> 53 | E23: ='Platform Setup'!$Q$23 -> Global | F23: One row per article published or syndicated. | G23: 1) Satellite blog: one repurposed article/month with canonical. 2) Never let it outrank the main site — always canonical + link home. | H23: Referral visits | I23: 30 min/month
A24: ='Platform Setup'!$B$24 -> Blogger | B24: ='Platform Setup'!$C$24 -> Publishing | C24: ='Platform Setup'!$D$24 -> Low | D24: ='Platform Setup'!$P$24 -> 98 | E24: ='Platform Setup'!$Q$24 -> Global | F24: One row per article published or syndicated. | G24: 1) Same satellite rules as WordPress.com — one repurpose/month, canonical set, link home. | H24: Referral visits | I24: 20 min/month
A25: ='Platform Setup'!$B$25 -> Tumblr | B25: ='Platform Setup'!$C$25 -> Publishing | C25: ='Platform Setup'!$D$25 -> Low | D25: ='Platform Setup'!$P$25 -> 99 | E25: ='Platform Setup'!$Q$25 -> Global | F25: One row per post published. | G25: 1) Low priority: reblog visual content monthly. 2) Tag by topic; skip if time-pressed. | H25: Referral visits | I25: 15 min/month
A26: ='Platform Setup'!$B$26 -> Vocal Media | B26: ='Platform Setup'!$C$26 -> Publishing | C26: ='Platform Setup'!$D$26 -> Low | D26: ='Platform Setup'!$P$26 -> 100 | E26: ='Platform Setup'!$Q$26 -> Global | F26: One row per story published. | G26: 1) One career-story piece/quarter (human angle, credential mention). 2) Link to author page. | H26: Reads + referrals | I26: 1 h/quarter
A27: ='Platform Setup'!$B$27 -> DEV Community | B27: ='Platform Setup'!$C$27 -> Publishing | C27: ='Platform Setup'!$D$27 -> Low | D27: ='Platform Setup'!$P$27 -> 101 | E27: ='Platform Setup'!$Q$27 -> Global | F27: One row per article. Comments on other people's posts are engagement. | G27: 1) Only for Certuvo engineering content (if tooling ships). 2) One technical post/quarter max. | H27: Followers + referrals | I27: 1 h/quarter
A28: ='Platform Setup'!$B$28 -> Hashnode | B28: ='Platform Setup'!$C$28 -> Publishing | C28: ='Platform Setup'!$D$28 -> Low | D28: ='Platform Setup'!$P$28 -> 102 | E28: ='Platform Setup'!$Q$28 -> Global | F28: One row per article published. | G28: 1) Mirror of DEV Community play — Certuvo technical content only, quarterly. | H28: Referrals | I28: 1 h/quarter
A29: ='Platform Setup'!$B$29 -> Quora | B29: ='Platform Setup'!$C$29 -> Community | C29: ='Platform Setup'!$D$29 -> High | D29: ='Platform Setup'!$P$29 -> 25 | E29: ='Platform Setup'!$Q$29 -> US + India | F29: One Quora value. Space vs answer is the Activity type, not the platform. | G29: 1) Answer 3 high-traffic questions/week from saved topic feeds (project controls, planning, EVM). 2) Genuine answer first, one relevant link max. 3) Log answers in Community & PR with URL. | H29: Answer views + upvotes; referral visits | I29: 1.5 h
A30: ='Platform Setup'!$B$30 -> Reddit | B30: ='Platform Setup'!$C$30 -> Community | C30: ='Platform Setup'!$D$30 -> High | D30: ='Platform Setup'!$P$30 -> 26 | E30: ='Platform Setup'!$Q$30 -> US, UK, anglosphere | F30: One row per thread started or substantive answer given — never per upvote or one-line comment. | G30: 1) Contribute helpfully in the subreddits named on Platform Setup — r/projectmanagement, r/construction, r/civilengineering, r/PMP, r/artificial — value first, weeks before any link. 2) Never paste identical answers. 3) AMA once credibility exists. Reddit is the #1 AI-cited domain — presence here feeds AI answers. | H30: Karma trend + non-penalised mentions | I30: 1.5 h
A31: ='Platform Setup'!$B$31 -> Planning Planet | B31: ='Platform Setup'!$C$31 -> Community | C31: ='Platform Setup'!$D$31 -> High | D31: ='Platform Setup'!$P$31 -> 27 | E31: ='Platform Setup'!$Q$31 -> Global (UK-run; heavy Gulf / oil & gas) | F31: The project controls forum (incl. Guild of Project Controls). Exactly our audience. | G31: 1) 3 forum answers/week — this is EXACTLY our audience. 2) Build named-expert reputation; signature link once established. 3) Note active senior practitioners as honorary-outreach candidates. | H31: Answers + honorary leads sourced | I31: 1.5 h
A32: ='Platform Setup'!$B$32 -> PMI Community (ProjectManagement.com) | B32: ='Platform Setup'!$C$32 -> Community | C32: ='Platform Setup'!$D$32 -> High | D32: ='Platform Setup'!$P$32 -> 28 | E32: ='Platform Setup'!$Q$32 -> Global | F32: Largest adjacent professional audience. | G32: 1) 2 discussion contributions/week. 2) Respect house rules — no direct promotion; expertise only. 3) Watch for content-contribution openings (they take articles). | H32: Contributions + profile views | I32: 1 h
A33: ='Platform Setup'!$B$33 -> Facebook Groups | B33: ='Platform Setup'!$C$33 -> Community | C33: ='Platform Setup'!$D$33 -> Medium | D33: ='Platform Setup'!$P$33 -> 54 | E33: ='Platform Setup'!$Q$33 -> India, SE Asia, MENA — weak for UK/US professionals | F33: One row per discussion started or substantive answer given. | G33: 1) 3 useful answers/week across the 10 joined groups (Gulf/India planner groups). 2) Value first; link only when asked or clearly helpful. 3) Log in Community & PR. | H33: Answers + leads sourced | I33: 1 h
A34: ='Platform Setup'!$B$34 -> Discord | B34: ='Platform Setup'!$C$34 -> Community | C34: ='Platform Setup'!$D$34 -> Medium | D34: ='Platform Setup'!$P$34 -> 55 | E34: ='Platform Setup'!$Q$34 -> Global | F34: One row per session of helping, not per message. Record minutes honestly. | G34: 1) Be present in 2-3 PM/engineering servers; answer when pinged-relevant. 2) No drive-by promo — servers ban fast. | H34: Helpful answers logged | I34: 45 min
A35: ='Platform Setup'!$B$35 -> Slack Communities | B35: ='Platform Setup'!$C$35 -> Community | C35: ='Platform Setup'!$D$35 -> Medium | D35: ='Platform Setup'!$P$35 -> 56 | E35: ='Platform Setup'!$Q$35 -> Global | F35: One row per session of helping, not per message. | G35: 1) Same as Discord: 2-3 communities, answer genuinely, DM only when invited. | H35: Answers + DMs earned | I35: 45 min
A36: ='Platform Setup'!$B$36 -> WhatsApp Channel | B36: ='Platform Setup'!$C$36 -> Community | C36: ='Platform Setup'!$D$36 -> Medium | D36: ='Platform Setup'!$P$36 -> 57 | E36: ='Platform Setup'!$Q$36 -> India + Gulf; near-universal outside the US | F36: Broadcast channel. The 1:1 reminder tool is WhatsApp Business API / SMS. | G36: 1) One value broadcast/week max (exam tip, deadline reminder, new resource). 2) Grow the channel via site + email footers. 3) Log sends in DAILY ENTRY ('WhatsApp / Telegram / SMS sent'). | H36: Subscribers + view rate | I36: 30 min
A37: ='Platform Setup'!$B$37 -> AACE Communities | B37: ='Platform Setup'!$C$37 -> Community | C37: ='Platform Setup'!$D$37 -> Medium | D37: ='Platform Setup'!$P$37 -> 58 | E37: ='Platform Setup'!$Q$37 -> Global | F37: Cost-engineering overlap; engage respectfully — peer body. | G37: 1) Respectful peer-body presence: answer technically, never conquest inside their house. 2) Note engaged members for individual outreach OUTSIDE the community. | H37: Reputation (no complaints) + leads noted | I37: 45 min
A38: ='Platform Setup'!$B$38 -> Telegram Channel | B38: ='Platform Setup'!$C$38 -> Community | C38: ='Platform Setup'!$D$38 -> Low | D38: ='Platform Setup'!$P$38 -> 103 | E38: ='Platform Setup'!$Q$38 -> India, Russia, MENA | F38: One row per broadcast sent — put the subscriber count in 'How many'. | G38: 1) Mirror WhatsApp Channel content (India/MENA audience). 2) One value post/week; pin the current campaign. 3) Log sends in DAILY ENTRY. | H38: Subscribers + views per post | I38: 20 min
A39: ='Platform Setup'!$B$39 -> Project Management Stack Exchange | B39: ='Platform Setup'!$C$39 -> Community | C39: ='Platform Setup'!$D$39 -> Low | D39: ='Platform Setup'!$P$39 -> 104 | E39: ='Platform Setup'!$Q$39 -> Global | F39: Small but evergreen Q&A footprint. | G39: 1) One thorough answer/week on scheduling/EVM questions. 2) Evergreen answers rank in Google for years — pick questions matching Keyword Plan terms. | H39: Answer score + cumulative views | I39: 45 min
A40: ='Platform Setup'!$B$40 -> GitHub | B40: ='Platform Setup'!$C$40 -> Community | C40: ='Platform Setup'!$D$40 -> Low | D40: ='Platform Setup'!$P$40 -> 105 | E40: ='Platform Setup'!$Q$40 -> Global | F40: Only if Certuvo open-sources tooling. | G40: 1) Only if Certuvo open-sources tooling: keep README + examples current, answer issues weekly. | H40: Stars + issue response time | I40: 1 h (if active)
...

Sheet PR & Target Directory
A1: PR & TARGET DIRECTORY — named routes, verified August 2026
A2: ◀ MAP | B2: The actual places, people and submission routes behind the generic platform rows — researched and verified live. Yellow columns are the team's tracker. Re-verify a route before relying on it if more than 6 months have passed.
A4: Category | B4: Target | C4: Route / where | D4: What to do | E4: Owner | F4: Status | G4: Notes / result
A5: UK course directories | B5: Reed Courses | C5: reed.co.uk/courses/providers | D5: Apply as provider; commercial terms on application
B6: findcourses.co.uk | C6: via their sales team | D6: List PCL-AI / PFL-AI / PML-AI with UTM links
B7: Emagister UK | C7: emagister.co.uk | D7: Lead-gen listing; compare cost per lead after 90 days
B8: Coursecheck | C8: coursecheck.com/training-providers | D8: Provider signup + review capture at end of each cohort
A9: Gulf directories | B9: Laimoon | C9: providers.laimoon.com | D9: Free provider listing (UAE + Saudi)
B10: Coursetakers.ae | C10: coursetakers.ae | D10: Provider signup; UAE course aggregator
B11: Edarabia | C11: edarabia.com | D11: Submit institution listing + reviews
A12: Global directories | B12: Class Central | C12: classcentral.com | D12: Request provider indexing AND pitch a free intro certificate into their editorial lists
A13: CPD accreditation | B13: The CPD Certification Service | C13: cpduk.co.uk/become-accredited | D13: Largest/oldest UK accreditor — start here
B14: CPD Standards Office | C14: cpdstandards.com/become-accredited | D14: Research-based accreditor; alternative quote
B15: The CPD Group | C15: thecpd.group | D15: 9,900+ providers; certified by The CPD Register
A16: Podcasts (guesting) | B16: Project Chatter | C16: projectchatter.com/be-a-guest | D16: TOP TARGET — the project controls podcast; direct guest form; 45-60 min remote
B17: Beyond Deadlines | C17: beyond-deadlines.com | D17: Construction planning/scheduling audience
B18: PM Happy Hour | C18: pmhappyhour.com | D18: Practitioner-guest format
B19: People and Projects | C19: peopleandprojectspodcast.com | D19: Long-running interview format
B20: Manage This (Velociteach) | C20: velociteach.com | D20: 1st/3rd Tuesdays; pitch via contact form
A21: Publications | B21: PM World Journal | C21: pmworldjournal.com/authors | D21: PRIORITY — pitch a named-author monthly series to the editor
B22: Project Times | C22: projecttimes.com/contribute | D22: Word-doc submission; evergreen career articles
B23: Training Industry | C23: trainingindustry.com/collaborate-with-us + editor@trainingindustry.com | D23: Bylined article + research Top Training Companies criteria
B24: eLearning Industry | C24: elearningindustry.com/post-here | D24: Author profile + L&D-angle articles (no HR content)
B25: PBC Today | C25: pbctoday.co.uk | D25: 700-word UK construction opinion pieces
B26: The Digital Project Manager | C26: thedigitalprojectmanager.com | D26: Expert contribution + their podcast + certification roundups
A27: Publications (Gulf) | B27: Construction Week ME | C27: constructionweekonline.com | D27: Journalist roster on Muck Rack; offer expert commentary
B28: CBNME | C28: cbnme.com | D28: Gulf construction business news; pitch editors
A29: Publications (academic) | B29: Journal of Project Management | C29: growingscience.com/jpm | D29: Open access, covers project controls, no submission charge
A30: Journalist requests | B30: Source of Sources (SOS) | C30: free subscription | D30: 3 on-expertise answers weekly, 80-120 words, data-led
B31: Help a B2B Writer | C31: free, B2B-only | D31: Respond same day
B32: ResponseSource (UK) | C32: responsesource.com | D32: Paid; Business/Education/Construction categories; 2-hour answers
B33: #journorequest | C33: X and Bluesky, twice daily | D33: Fastest channel; search saved daily
A34: Events & awards | B34: Project Controls Expo UK | C34: projectcontrolexpo.com/uk | D34: London (Wembley) 2-4 Nov 2026, 2,000+ delegates — speaker application + Awards entry
B35: Project Controls Expo USA | C35: projectcontrolexpo.com | D35: Washington DC 5-7 Oct 2026
B36: Project Controls Expo Australia | C36: projectcontrolexpo.com | D36: Melbourne (MCG) 23-25 Nov 2026
B37: Project Control Summit | C37: projectcontrolsummit.com | D37: Apply to present
B38: Advancing Project Controls | C38: advancing-project-controls.com | D38: US conference; speaking/sponsor slots
A39: Speaker directories | B39: Sessionize | C39: sessionize.com — free | D39: Profiles for 2 PCI leaders + 3 CFP applications/quarter
